Workbook

Sheet měsíc vzorový 2025
A1: VÝNOSY | H1: týden 1 (zpravidla dělený s předchozím měsícem) | K1: týden 2 | N1: týden 3 | Q1: týden 4 | T1: týden 5 (zpravidla dělený s následujícím měsícem)
A2: Středisko/pracovník | B2: plán měsíce | C2: skutečnost měsíce | D2: rozdíl | E2: počet intervencí | F2: odpracováno hod. | H2: výkony /týden | I2: počet intervencí | J2: odpracováno hod. | K2: výkony /týden | L2: počet intervencí | M2: odpracováno hod. | N2: výkony /týden | O2: počet intervencí | P2: odpracováno hod. | Q2: výkony /týden | R2: počet intervencí | S2: odpracováno hod. | T2: výkony /týden | U2: počet intervencí | V2: odpracováno hod.
A3: výnosy CDZ Ústí | B3: =SUM(B4:B11) -> 1190000 | C3: =SUM(C4:C11) -> 0 | D3: =SUM(D4:D11) -> -1190000 | E3: =SUM(E4:E11) -> 0 | F3: =SUM(F4:F11) -> 0 | H3: =SUM(H4:H11) -> 0 | I3: =SUM(I4:I11) -> 0 | J3: =SUM(J4:J11) -> 0 | K3: =SUM(K4:K11) -> 0 | L3: =SUM(L4:L11) -> 0 | M3: =SUM(M4:M11) -> 0 | N3: =SUM(N4:N11) -> 0 | O3: =SUM(O4:O11) -> 0 | ... V3: =SUM(V4:V11) -> 0
A4: psych. s. 1 - NÁGLOVÁ | B4: 200000 | C4: =+H4+K4+N4+Q4+T4 -> 0 | D4: =+C4-B4 -> -200000 | E4: =+I4+L4+O4+R4+U4 -> 0 | F4: =+J4+M4+P4+S4+V4 -> 0
A5: psych. s. 2 - HAJASOVÁ | B5: 200000 | C5: =+H5+K5+N5+Q5+T5 -> 0 | D5: =+C5-B5 -> -200000 | E5: =+I5+L5+O5+R5+U5 -> 0 | F5: =+J5+M5+P5+S5+V5 -> 0
A6: psych. s. 3 - KAŠPÁRKOVÁ/Pekárová | B6: 200000 | C6: =+H6+K6+N6+Q6+T6 -> 0 | D6: =+C6-B6 -> -200000 | E6: =+I6+L6+O6+R6+U6 -> 0 | F6: =+J6+M6+P6+S6+V6 -> 0
A7: psych. s. 4 - Milfajtová | B7: 200000 | C7: =+H7+K7+N7+Q7+T7 -> 0 | D7: =+C7-B7 -> -200000 | E7: =+I7+L7+O7+R7+U7 -> 0 | F7: =+J7+M7+P7+S7+V7 -> 0
A8: psychiatr - GÁBEL 0,2 | B8: =450000*0.2 -> 90000 | C8: =+H8+K8+N8+Q8+T8 -> 0 | D8: =+C8-B8 -> -90000 | E8: =+I8+L8+O8+R8+U8 -> 0 | F8: =+J8+M8+P8+S8+V8 -> 0
A9: psychiatr - PFEIFFER 0,5 na březen + doktorka | B9: =450000*0.5 -> 225000 | C9: =+H9+K9+N9+Q9+T9 -> 0 | D9: =+C9-B9 -> -225000 | E9: =+I9+L9+O9+R9+U9 -> 0 | F9: =+J9+M9+P9+S9+V9 -> 0
A10: psycholog 1 - 0,5 | B10: 75000 | C10: =+H10+K10+N10+Q10+T10 -> 0 | D10: =+C10-B10 -> -75000 | E10: =+I10+L10+O10+R10+U10 -> 0 | F10: =+J10+M10+P10+S10+V10 -> 0
A11: psycholog 2 | B11: 0 | C11: =+H11+K11+N11+Q11+T11 -> 0 | D11: =+C11-B11 -> 0 | E11: =+I11+L11+O11+R11+U11 -> 0 | F11: =+J11+M11+P11+S11+V11 -> 0
A12: výnosy CDZ Chomutov | B12: =SUM(B13:B20) -> 1100000 | C12: =SUM(C13:C20) -> 0 | D12: =SUM(D13:D20) -> -1100000 | E12: =SUM(E13:E20) -> 0 | F12: =SUM(F13:F20) -> 0 | H12: =SUM(H13:H20) -> 0 | I12: =SUM(I13:I20) -> 0 | J12: =SUM(J13:J20) -> 0 | K12: =SUM(K13:K20) -> 0 | L12: =SUM(L13:L20) -> 0 | M12: =SUM(M13:M20) -> 0 | N12: =SUM(N13:N20) -> 0 | O12: =SUM(O13:O20) -> 0 | ... V12: =SUM(V13:V20) -> 0
A13: psych. s 1 - Blažková | B13: 200000 | C13: =+H13+K13+N13+Q13+T13 -> 0 | D13: =+C13-B13 -> -200000 | E13: =+I13+L13+O13+R13+U13 -> 0 | F13: =+J13+M13+P13+S13+V13 -> 0
A14: psych. s 2 - Pátková od 1.3 | B14: 200000 | C14: =+H14+K14+N14+Q14+T14 -> 0 | D14: =+C14-B14 -> -200000 | E14: =+I14+L14+O14+R14+U14 -> 0 | F14: =+J14+M14+P14+S14+V14 -> 0
A15: psych. s 3 | B15: 200000 | C15: =+H15+K15+N15+Q15+T15 -> 0 | D15: =+C15-B15 -> -200000 | E15: =+I15+L15+O15+R15+U15 -> 0 | F15: =+J15+M15+P15+S15+V15 -> 0
A16: psych. s 4 | B16: 200000 | C16: =+H16+K16+N16+Q16+T16 -> 0 | D16: =+C16-B16 -> -200000 | E16: =+I16+L16+O16+R16+U16 -> 0 | F16: =+J16+M16+P16+S16+V16 -> 0
A17: psychiatr 1 - 0,5 od 1.4 | B17: =450000*0.5 -> 225000 | C17: =+H17+K17+N17+Q17+T17 -> 0 | D17: =+C17-B17 -> -225000 | E17: =+I17+L17+O17+R17+U17 -> 0 | F17: =+J17+M17+P17+S17+V17 -> 0
A18: psychiatr 2 | B18: 0 | C18: =+H18+K18+N18+Q18+T18 -> 0 | D18: =+C18-B18 -> 0 | E18: =+I18+L18+O18+R18+U18 -> 0 | F18: =+J18+M18+P18+S18+V18 -> 0
A19: psycholog 1 - 0,5 | B19: 75000 | C19: =+H19+K19+N19+Q19+T19 -> 0 | D19: =+C19-B19 -> -75000 | E19: =+I19+L19+O19+R19+U19 -> 0 | F19: =+J19+M19+P19+S19+V19 -> 0
A20: psycholog 2 | B20: 0 | C20: =+H20+K20+N20+Q20+T20 -> 0 | D20: =+C20-B20 -> 0 | E20: =+I20+L20+O20+R20+U20 -> 0 | F20: =+J20+M20+P20+S20+V20 -> 0
A21: výnosy CDZ Žatec | B21: =SUM(B22:B29) -> 1100000 | C21: =SUM(C22:C29) -> 0 | D21: =SUM(D22:D29) -> -1100000 | E21: =SUM(E22:E29) -> 0 | F21: =SUM(F22:F29) -> 0 | H21: =SUM(H22:H29) -> 0 | I21: =SUM(I22:I29) -> 0 | J21: =SUM(J22:J29) -> 0 | K21: =SUM(K22:K29) -> 0 | L21: =SUM(L22:L29) -> 0 | M21: =SUM(M22:M29) -> 0 | N21: =SUM(N22:N29) -> 0 | O21: =SUM(O22:O29) -> 0 | ... V21: =SUM(V22:V29) -> 0
A22: psych. s 1 - ZELENKOVÁ | B22: 200000 | C22: =+H22+K22+N22+Q22+T22 -> 0 | D22: =+C22-B22 -> -200000 | E22: =+I22+L22+O22+R22+U22 -> 0 | F22: =+J22+M22+P22+S22+V22 -> 0
A23: psych. s 2 - Štěpánka … | B23: 200000 | C23: =+H23+K23+N23+Q23+T23 -> 0 | D23: =+C23-B23 -> -200000 | E23: =+I23+L23+O23+R23+U23 -> 0 | F23: =+J23+M23+P23+S23+V23 -> 0
A24: psych. s 3 - Bečvářová | B24: 200000 | C24: =+H24+K24+N24+Q24+T24 -> 0 | D24: =+C24-B24 -> -200000 | E24: =+I24+L24+O24+R24+U24 -> 0 | F24: =+J24+M24+P24+S24+V24 -> 0
A25: všeob. s 4 - Dušková | B25: 200000 | C25: =+H25+K25+N25+Q25+T25 -> 0 | D25: =+C25-B25 -> -200000 | E25: =+I25+L25+O25+R25+U25 -> 0 | F25: =+J25+M25+P25+S25+V25 -> 0
A26: psychiatr 1 - 0,5 od 1.4 | B26: =450000*0.5 -> 225000 | C26: =+H26+K26+N26+Q26+T26 -> 0 | D26: =+C26-B26 -> -225000 | E26: =+I26+L26+O26+R26+U26 -> 0 | F26: =+J26+M26+P26+S26+V26 -> 0
A27: psychiatr 2 | B27: 0 | C27: =+H27+K27+N27+Q27+T27 -> 0 | D27: =+C27-B27 -> 0 | E27: =+I27+L27+O27+R27+U27 -> 0 | F27: =+J27+M27+P27+S27+V27 -> 0
A28: psycholog 1 - 0,5 | B28: 75000 | C28: =+H28+K28+N28+Q28+T28 -> 0 | D28: =+C28-B28 -> -75000 | E28: =+I28+L28+O28+R28+U28 -> 0 | F28: =+J28+M28+P28+S28+V28 -> 0
A29: psycholog 2 | B29: 0 | C29: =+H29+K29+N29+Q29+T29 -> 0 | D29: =+C29-B29 -> 0 | E29: =+I29+L29+O29+R29+U29 -> 0 | F29: =+J29+M29+P29+S29+V29 -> 0
A30: výnosy CDZ Litoměřice | B30: =SUM(B31:B38) -> 1100000 | C30: =SUM(C31:C38) -> 0 | D30: =SUM(D31:D38) -> -1100000 | E30: =SUM(E31:E38) -> 0 | F30: =SUM(F31:F38) -> 0 | H30: =SUM(H31:H38) -> 0 | I30: =SUM(I31:I38) -> 0 | J30: =SUM(J31:J38) -> 0 | K30: =SUM(K31:K38) -> 0 | L30: =SUM(L31:L38) -> 0 | M30: =SUM(M31:M38) -> 0 | N30: =SUM(N31:N38) -> 0 | O30: =SUM(O31:O38) -> 0 | ... V30: =SUM(V31:V38) -> 0
A31: psych. s 1 - Štréblová 0,2 od 1.3 od 5 celý | B31: 200000 | C31: =+H31+K31+N31+Q31+T31 -> 0 | D31: =+C31-B31 -> -200000 | E31: =+I31+L31+O31+R31+U31 -> 0 | F31: =+J31+M31+P31+S31+V31 -> 0
A32: psych. s 2 | B32: 200000 | C32: =+H32+K32+N32+Q32+T32 -> 0 | D32: =+C32-B32 -> -200000 | E32: =+I32+L32+O32+R32+U32 -> 0 | F32: =+J32+M32+P32+S32+V32 -> 0
A33: psych. s 3 | B33: 200000 | C33: =+H33+K33+N33+Q33+T33 -> 0 | D33: =+C33-B33 -> -200000 | E33: =+I33+L33+O33+R33+U33 -> 0 | F33: =+J33+M33+P33+S33+V33 -> 0
A34: psych. s 4 | B34: 200000 | C34: =+H34+K34+N34+Q34+T34 -> 0 | D34: =+C34-B34 -> -200000 | E34: =+I34+L34+O34+R34+U34 -> 0 | F34: =+J34+M34+P34+S34+V34 -> 0
A35: psychiatr 1 - 0,5 | B35: =450000*0.5 -> 225000 | C35: =+H35+K35+N35+Q35+T35 -> 0 | D35: =+C35-B35 -> -225000 | E35: =+I35+L35+O35+R35+U35 -> 0 | F35: =+J35+M35+P35+S35+V35 -> 0
A36: psychiatr 2 | B36: 0 | C36: =+H36+K36+N36+Q36+T36 -> 0 | D36: =+C36-B36 -> 0 | E36: =+I36+L36+O36+R36+U36 -> 0 | F36: =+J36+M36+P36+S36+V36 -> 0
A37: psycholog 1 - 0,5 | B37: 75000 | C37: =+H37+K37+N37+Q37+T37 -> 0 | D37: =+C37-B37 -> -75000 | E37: =+I37+L37+O37+R37+U37 -> 0 | F37: =+J37+M37+P37+S37+V37 -> 0
A38: psycholog 2 | B38: 0 | C38: =+H38+K38+N38+Q38+T38 -> 0 | D38: =+C38-B38 -> 0 | E38: =+I38+L38+O38+R38+U38 -> 0 | F38: =+J38+M38+P38+S38+V38 -> 0
A39: výnosy TDZ Děčín | B39: =SUM(B40:B41) -> 400000 | C39: =SUM(C40:C41) -> 0 | D39: =SUM(D40:D41) -> -400000 | E39: =SUM(E40:E41) -> 0 | F39: =SUM(F40:F41) -> 0 | H39: =SUM(H40:H41) -> 0 | I39: =SUM(I40:I41) -> 0 | J39: =SUM(J40:J41) -> 0 | K39: =SUM(K40:K41) -> 0 | L39: =SUM(L40:L41) -> 0 | M39: =SUM(M40:M41) -> 0 | N39: =SUM(N40:N41) -> 0 | O39: =SUM(O40:O41) -> 0 | ... V39: =SUM(V40:V41) -> 0
A40: psych. s 1 - Jirásková | B40: 200000 | C40: =+H40+K40+N40+Q40+T40 -> 0 | D40: =+C40-B40 -> -200000 | E40: =+I40+L40+O40+R40+U40 -> 0 | F40: =+J40+M40+P40+S40+V40 -> 0
...

Sheet leden 2025
A1: VÝNOSY | H1: týden 1 (zpravidla dělený s předchozím měsícem) | K1: týden 2 | N1: týden 3 | Q1: týden 4 | T1: týden 5 (zpravidla dělený s následujícím měsícem)
A2: Středisko/pracovník | B2: plán měsíce | C2: skutečnost měsíce | D2: rozdíl | E2: počet intervencí | F2: odpracováno hod. | H2: výkony /týden | I2: počet intervencí | J2: odpracováno hod. | K2: výkony /týden | L2: počet intervencí | M2: odpracováno hod. | N2: výkony /týden | O2: počet intervencí | P2: odpracováno hod. | Q2: výkony /týden | R2: počet intervencí | S2: odpracováno hod. | T2: výkony /týden | U2: počet intervencí | V2: odpracováno hod.
A3: výnosy CDZ Ústí | B3: =SUM(B4:B11) -> 915000 | C3: =SUM(C4:C11) -> 753882 | D3: =SUM(D4:D11) -> -161118 | E3: =SUM(E4:E11) -> 701 | F3: =SUM(F4:F11) -> 997.05 | H3: =SUM(H4:H11) -> 166363 | I3: =SUM(I4:I11) -> 139 | J3: =SUM(J4:J11) -> 224.9 | K3: =SUM(K4:K11) -> 180001 | L3: =SUM(L4:L11) -> 143 | M3: =SUM(M4:M11) -> 241.8 | N3: =SUM(N4:N11) -> 159140 | O3: =SUM(O4:O11) -> 123 | ... V3: =SUM(V4:V11) -> 0
A4: psych. s. 1 - NÁGLOVÁ | B4: 200000 | C4: =+H4+K4+N4+Q4+T4 -> 203197 | D4: =+C4-B4 -> 3197 | E4: =+I4+L4+O4+R4+U4 -> 213 | F4: =+J4+M4+P4+S4+V4 -> 300.45 | H4: 59212 | I4: 64 | J4: 86.2 | K4: 45535 | L4: 48 | M4: 70 | N4: 32413 | O4: 33 | P4: 48.35 | Q4: 66037 | R4: 68 | S4: 95.9
A5: psych. s. 2 - HAJASOVÁ | B5: 200000 | C5: =+H5+K5+N5+Q5+T5 -> 150551 | D5: =+C5-B5 -> -49449 | E5: =+I5+L5+O5+R5+U5 -> 124 | F5: =+J5+M5+P5+S5+V5 -> 223.3 | H5: 17941 | I5: 14 | J5: 28 | K5: 29704 | L5: 24 | M5: 44 | N5: 51750 | O5: 43 | P5: 75 | Q5: 51156 | R5: 43 | S5: 76.3
A6: psych. s. 3 - KAŠPÁRKOVÁ/Pekárová | B6: 200000 | C6: =+H6+K6+N6+Q6+T6 -> 160581 | D6: =+C6-B6 -> -39419 | E6: =+I6+L6+O6+R6+U6 -> 131 | F6: =+J6+M6+P6+S6+V6 -> 240 | H6: 43428 | I6: 35 | J6: 65.5 | K6: 53294 | L6: 43 | M6: 78 | N6: 16478 | O6: 15 | P6: 23.7 | Q6: 47381 | R6: 38 | S6: 72.8
A7: psych. s. 4 - Milfajtová | B7: 0 | C7: =+H7+K7+N7+Q7+T7 -> 0 | D7: =+C7-B7 -> 0 | E7: =+I7+L7+O7+R7+U7 -> 0 | F7: =+J7+M7+P7+S7+V7 -> 0
A8: psychiatr - GÁBEL 0,2 | B8: =450000*0.2 -> 90000 | C8: =+H8+K8+N8+Q8+T8 -> 7428 | D8: =+C8-B8 -> -82572 | E8: =+I8+L8+O8+R8+U8 -> 38 | F8: =+J8+M8+P8+S8+V8 -> 6.2 | H8: 0 | K8: 0 | L8: 0 | M8: 0 | N8: 391 | O8: 2 | P8: 0.2 | Q8: 7037 | R8: 36 | S8: 6
A9: psychiatr - PFEIFFER 0,5 na březen + doktorka | B9: =450000*0.5 -> 225000 | C9: =+H9+K9+N9+Q9+T9 -> 232125 | D9: =+C9-B9 -> 7125 | E9: =+I9+L9+O9+R9+U9 -> 195 | F9: =+J9+M9+P9+S9+V9 -> 227.1 | H9: 45782 | I9: 26 | J9: 45.2 | K9: 51468 | L9: 28 | M9: 49.8 | N9: 58108 | O9: 30 | P9: 58.1 | Q9: 76767 | R9: 111 | S9: 74
A10: psycholog 1 - 0,5 | B10: 0 | C10: =+H10+K10+N10+Q10+T10 -> 0 | D10: =+C10-B10 -> 0 | E10: =+I10+L10+O10+R10+U10 -> 0 | F10: =+J10+M10+P10+S10+V10 -> 0
A11: psycholog 2 | B11: 0 | C11: =+H11+K11+N11+Q11+T11 -> 0 | D11: =+C11-B11 -> 0 | E11: =+I11+L11+O11+R11+U11 -> 0 | F11: =+J11+M11+P11+S11+V11 -> 0
A12: výnosy CDZ Chomutov | B12: =SUM(B13:B20) -> 170000 | C12: =SUM(C13:C20) -> 100994 | D12: =SUM(D13:D20) -> -69006 | E12: =SUM(E13:E20) -> 153 | F12: =SUM(F13:F20) -> 177 | H12: =SUM(H13:H20) -> 22762 | I12: =SUM(I13:I20) -> 42 | J12: =SUM(J13:J20) -> 39.5 | K12: =SUM(K13:K20) -> 24240 | L12: =SUM(L13:L20) -> 33 | M12: =SUM(M13:M20) -> 42.7 | N12: =SUM(N13:N20) -> 25523 | O12: =SUM(O13:O20) -> 40 | ... V12: =SUM(V13:V20) -> 0
A13: psych. s 1 - Blažková | B13: =200000*0.85 -> 170000 | C13: =+H13+K13+N13+Q13+T13 -> 100994 | D13: =+C13-B13 -> -69006 | E13: =+I13+L13+O13+R13+U13 -> 153 | F13: =+J13+M13+P13+S13+V13 -> 177 | H13: 22762 | I13: 42 | J13: 39.5 | K13: 24240 | L13: 33 | M13: 42.7 | N13: 25523 | O13: 40 | P13: 45.3 | Q13: 28469 | R13: 38 | S13: 49.5
A14: psych. s 2 - Pátková od 1.3 | B14: 0 | C14: =+H14+K14+N14+Q14+T14 -> 0 | D14: =+C14-B14 -> 0 | E14: =+I14+L14+O14+R14+U14 -> 0 | F14: =+J14+M14+P14+S14+V14 -> 0
A15: psych. s 3 | B15: 0 | C15: =+H15+K15+N15+Q15+T15 -> 0 | D15: =+C15-B15 -> 0 | E15: =+I15+L15+O15+R15+U15 -> 0 | F15: =+J15+M15+P15+S15+V15 -> 0
A16: psych. s 4 | B16: 0 | C16: =+H16+K16+N16+Q16+T16 -> 0 | D16: =+C16-B16 -> 0 | E16: =+I16+L16+O16+R16+U16 -> 0 | F16: =+J16+M16+P16+S16+V16 -> 0
A17: psychiatr 1 - 0,5 od 1.4 | B17: 0 | C17: =+H17+K17+N17+Q17+T17 -> 0 | D17: =+C17-B17 -> 0 | E17: =+I17+L17+O17+R17+U17 -> 0 | F17: =+J17+M17+P17+S17+V17 -> 0
A18: psychiatr 2 | B18: 0 | C18: =+H18+K18+N18+Q18+T18 -> 0 | D18: =+C18-B18 -> 0 | E18: =+I18+L18+O18+R18+U18 -> 0 | F18: =+J18+M18+P18+S18+V18 -> 0
A19: psycholog 1 - 0,5 | B19: 0 | C19: =+H19+K19+N19+Q19+T19 -> 0 | D19: =+C19-B19 -> 0 | E19: =+I19+L19+O19+R19+U19 -> 0 | F19: =+J19+M19+P19+S19+V19 -> 0
A20: psycholog 2 | B20: 0 | C20: =+H20+K20+N20+Q20+T20 -> 0 | D20: =+C20-B20 -> 0 | E20: =+I20+L20+O20+R20+U20 -> 0 | F20: =+J20+M20+P20+S20+V20 -> 0
A21: výnosy CDZ Žatec | B21: =SUM(B22:B29) -> 170000 | C21: =SUM(C22:C29) -> 105887 | D21: =SUM(D22:D29) -> -64113 | E21: =SUM(E22:E29) -> 126 | F21: =SUM(F22:F29) -> 185.4 | H21: =SUM(H22:H29) -> 35359 | I21: =SUM(I22:I29) -> 39 | J21: =SUM(J22:J29) -> 62 | K21: =SUM(K22:K29) -> 24050 | L21: =SUM(L22:L29) -> 27 | M21: =SUM(M22:M29) -> 42.1 | N21: =SUM(N22:N29) -> 18629 | O21: =SUM(O22:O29) -> 25 | ... V21: =SUM(V22:V29) -> 0
A22: psych. s 1 - ZELENKOVÁ | B22: =200000*0.85 -> 170000 | C22: =+H22+K22+N22+Q22+T22 -> 105887 | D22: =+C22-B22 -> -64113 | E22: =+I22+L22+O22+R22+U22 -> 126 | F22: =+J22+M22+P22+S22+V22 -> 185.4 | H22: 35359 | I22: 39 | J22: 62 | K22: 24050 | L22: 27 | M22: 42.1 | N22: 18629 | O22: 25 | P22: 32.4 | Q22: 27849 | R22: 35 | S22: 48.9
A23: psych. s 2 - Štěpánka … | B23: 0 | C23: =+H23+K23+N23+Q23+T23 -> 0 | D23: =+C23-B23 -> 0 | E23: =+I23+L23+O23+R23+U23 -> 0 | F23: =+J23+M23+P23+S23+V23 -> 0
A24: psych. s 3 - Bečvářová | B24: 0 | C24: =+H24+K24+N24+Q24+T24 -> 0 | D24: =+C24-B24 -> 0 | E24: =+I24+L24+O24+R24+U24 -> 0 | F24: =+J24+M24+P24+S24+V24 -> 0
A25: všeob. s 4 - Dušková | B25: 0 | C25: =+H25+K25+N25+Q25+T25 -> 0 | D25: =+C25-B25 -> 0 | E25: =+I25+L25+O25+R25+U25 -> 0 | F25: =+J25+M25+P25+S25+V25 -> 0
A26: psychiatr 1 - 0,5 od 1.4 | B26: 0 | C26: =+H26+K26+N26+Q26+T26 -> 0 | D26: =+C26-B26 -> 0 | E26: =+I26+L26+O26+R26+U26 -> 0 | F26: =+J26+M26+P26+S26+V26 -> 0
A27: psychiatr 2 | B27: 0 | C27: =+H27+K27+N27+Q27+T27 -> 0 | D27: =+C27-B27 -> 0 | E27: =+I27+L27+O27+R27+U27 -> 0 | F27: =+J27+M27+P27+S27+V27 -> 0
A28: psycholog 1 - 0,5 | B28: 0 | C28: =+H28+K28+N28+Q28+T28 -> 0 | D28: =+C28-B28 -> 0 | E28: =+I28+L28+O28+R28+U28 -> 0 | F28: =+J28+M28+P28+S28+V28 -> 0
A29: psycholog 2 | B29: 0 | C29: =+H29+K29+N29+Q29+T29 -> 0 | D29: =+C29-B29 -> 0 | E29: =+I29+L29+O29+R29+U29 -> 0 | F29: =+J29+M29+P29+S29+V29 -> 0
A30: výnosy CDZ Litoměřice | B30: =SUM(B31:B38) -> 0 | C30: =SUM(C31:C38) -> 0 | D30: =SUM(D31:D38) -> 0 | E30: =SUM(E31:E38) -> 0 | F30: =SUM(F31:F38) -> 0 | H30: =SUM(H31:H38) -> 0 | I30: =SUM(I31:I38) -> 0 | J30: =SUM(J31:J38) -> 0 | K30: =SUM(K31:K38) -> 0 | L30: =SUM(L31:L38) -> 0 | M30: =SUM(M31:M38) -> 0 | N30: =SUM(N31:N38) -> 0 | O30: =SUM(O31:O38) -> 0 | ... V30: =SUM(V31:V38) -> 0
A31: psych. s 1 - Štréblová 0,2 od 1.3 od 5 celý | B31: 0 | C31: =+H31+K31+N31+Q31+T31 -> 0 | D31: =+C31-B31 -> 0 | E31: =+I31+L31+O31+R31+U31 -> 0 | F31: =+J31+M31+P31+S31+V31 -> 0
A32: psych. s 2 | B32: 0 | C32: =+H32+K32+N32+Q32+T32 -> 0 | D32: =+C32-B32 -> 0 | E32: =+I32+L32+O32+R32+U32 -> 0 | F32: =+J32+M32+P32+S32+V32 -> 0
A33: psych. s 3 | B33: 0 | C33: =+H33+K33+N33+Q33+T33 -> 0 | D33: =+C33-B33 -> 0 | E33: =+I33+L33+O33+R33+U33 -> 0 | F33: =+J33+M33+P33+S33+V33 -> 0
A34: psych. s 4 | B34: 0 | C34: =+H34+K34+N34+Q34+T34 -> 0 | D34: =+C34-B34 -> 0 | E34: =+I34+L34+O34+R34+U34 -> 0 | F34: =+J34+M34+P34+S34+V34 -> 0
A35: psychiatr 1 - 0,5 | B35: 0 | C35: =+H35+K35+N35+Q35+T35 -> 0 | D35: =+C35-B35 -> 0 | E35: =+I35+L35+O35+R35+U35 -> 0 | F35: =+J35+M35+P35+S35+V35 -> 0
A36: psychiatr 2 | B36: 0 | C36: =+H36+K36+N36+Q36+T36 -> 0 | D36: =+C36-B36 -> 0 | E36: =+I36+L36+O36+R36+U36 -> 0 | F36: =+J36+M36+P36+S36+V36 -> 0
A37: psycholog 1 - 0,5 | B37: 0 | C37: =+H37+K37+N37+Q37+T37 -> 0 | D37: =+C37-B37 -> 0 | E37: =+I37+L37+O37+R37+U37 -> 0 | F37: =+J37+M37+P37+S37+V37 -> 0
A38: psycholog 2 | B38: 0 | C38: =+H38+K38+N38+Q38+T38 -> 0 | D38: =+C38-B38 -> 0 | E38: =+I38+L38+O38+R38+U38 -> 0 | F38: =+J38+M38+P38+S38+V38 -> 0
A39: výnosy TDZ Děčín | B39: =SUM(B40:B41) -> 170000 | C39: =SUM(C40:C41) -> 18487 | D39: =SUM(D40:D41) -> -151513 | E39: =SUM(E40:E41) -> 33 | F39: =SUM(F40:F41) -> 32.25 | H39: =SUM(H40:H41) -> 16682 | I39: =SUM(I40:I41) -> 33 | J39: =SUM(J40:J41) -> 29.15 | K39: =SUM(K40:K41) -> 10932 | L39: =SUM(L40:L41) -> 20 | M39: =SUM(M40:M41) -> 19.1 | N39: =SUM(N40:N41) -> 15826 | O39: =SUM(O40:O41) -> 30 | ... V39: =SUM(V40:V41) -> 0
A40: psych. s 1 - Jirásková | B40: =200000*0.85 -> 170000 | C40: =+H40+K40+N40+Q40+T40 -> 18487 | D40: =+C40-B40 -> -151513 | E40: =+I40+L40+O40+R40+U40 -> 33 | F40: =+J40+M40+P40+S40+V40 -> 32.25 | H40: 16682 | I40: 33 | J40: 29.15 | K40: 10932 | L40: 20 | M40: 19.1 | N40: 15826 | O40: 30 | P40: 27.85 | Q40: -24953 | R40: -50 | S40: -43.85
...

Sheet únor 2025
A1: VÝNOSY | H1: týden 1 (zpravidla dělený s předchozím měsícem) | K1: týden 2 | N1: týden 3 | Q1: týden 4 | T1: týden 5 (zpravidla dělený s následujícím měsícem)
A2: Středisko/pracovník | B2: plán měsíce | C2: skutečnost měsíce | D2: rozdíl | E2: počet intervencí | F2: odpracováno hod. | H2: výkony /týden | I2: počet intervencí | J2: odpracováno hod. | K2: výkony /týden | L2: počet intervencí | M2: odpracováno hod. | N2: výkony /týden | O2: počet intervencí | P2: odpracováno hod. | Q2: výkony /týden | R2: počet intervencí | S2: odpracováno hod. | T2: výkony /týden | U2: počet intervencí | V2: odpracováno hod.
A3: výnosy CDZ Ústí | B3: =SUM(B4:B11) -> 915000 | C3: =SUM(C4:C11) -> 717986 | D3: =SUM(D4:D11) -> -197014 | E3: =SUM(E4:E11) -> 0 | F3: =SUM(F4:F11) -> 0 | H3: =SUM(H4:H11) -> 0 | I3: =SUM(I4:I11) -> 0 | J3: =SUM(J4:J11) -> 0 | K3: =SUM(K4:K11) -> 0 | L3: =SUM(L4:L11) -> 0 | M3: =SUM(M4:M11) -> 0 | N3: =SUM(N4:N11) -> 0 | O3: =SUM(O4:O11) -> 0 | ... V3: =SUM(V4:V11) -> 0
A4: psych. s. 1 - NÁGLOVÁ | B4: 200000 | C4: 201098 | D4: =+C4-B4 -> 1098 | E4: =+I4+L4+O4+R4+U4 -> 0 | F4: =+J4+M4+P4+S4+V4 -> 0
A5: psych. s. 2 - HAJASOVÁ | B5: 200000 | C5: 94246 | D5: =+C5-B5 -> -105754 | E5: =+I5+L5+O5+R5+U5 -> 0 | F5: =+J5+M5+P5+S5+V5 -> 0
A6: psych. s. 3 - KAŠPÁRKOVÁ/Pekárová | B6: 200000 | C6: 195875 | D6: =+C6-B6 -> -4125 | E6: =+I6+L6+O6+R6+U6 -> 0 | F6: =+J6+M6+P6+S6+V6 -> 0
A7: psych. s. 4 - | B7: 0 | C7: =+H7+K7+N7+Q7+T7 -> 0 | D7: =+C7-B7 -> 0 | E7: =+I7+L7+O7+R7+U7 -> 0 | F7: =+J7+M7+P7+S7+V7 -> 0
A8: psychiatr - GÁBEL 0,2 | B8: =450000*0.2 -> 90000 | C8: 5473 | D8: =+C8-B8 -> -84527 | E8: =+I8+L8+O8+R8+U8 -> 0 | F8: =+J8+M8+P8+S8+V8 -> 0
A9: psychiatr - PFEIFFER 0,5 na březen + doktorka | B9: =450000*0.5 -> 225000 | C9: 221294 | D9: =+C9-B9 -> -3706 | E9: =+I9+L9+O9+R9+U9 -> 0 | F9: =+J9+M9+P9+S9+V9 -> 0
A10: psycholog 1 - 0,5 | B10: 0 | C10: =+H10+K10+N10+Q10+T10 -> 0 | D10: =+C10-B10 -> 0 | E10: =+I10+L10+O10+R10+U10 -> 0 | F10: =+J10+M10+P10+S10+V10 -> 0
A11: psycholog 2 | B11: 0 | C11: =+H11+K11+N11+Q11+T11 -> 0 | D11: =+C11-B11 -> 0 | E11: =+I11+L11+O11+R11+U11 -> 0 | F11: =+J11+M11+P11+S11+V11 -> 0
A12: výnosy CDZ Chomutov | B12: =SUM(B13:B20) -> 170000 | C12: =SUM(C13:C20) -> 75476 | D12: =SUM(D13:D20) -> -94524 | E12: =SUM(E13:E20) -> 0 | F12: =SUM(F13:F20) -> 0 | H12: =SUM(H13:H20) -> 0 | I12: =SUM(I13:I20) -> 0 | J12: =SUM(J13:J20) -> 0 | K12: =SUM(K13:K20) -> 0 | L12: =SUM(L13:L20) -> 0 | M12: =SUM(M13:M20) -> 0 | N12: =SUM(N13:N20) -> 0 | O12: =SUM(O13:O20) -> 0 | ... V12: =SUM(V13:V20) -> 0
A13: psych. s 1 - Blažková | B13: =200000*0.85 -> 170000 | C13: 75476 | D13: =+C13-B13 -> -94524 | E13: =+I13+L13+O13+R13+U13 -> 0 | F13: =+J13+M13+P13+S13+V13 -> 0
A14: psych. s 2 - Pátková od 1.3 | B14: 0 | C14: =+H14+K14+N14+Q14+T14 -> 0 | D14: =+C14-B14 -> 0 | E14: =+I14+L14+O14+R14+U14 -> 0 | F14: =+J14+M14+P14+S14+V14 -> 0
A15: psych. s 3 | B15: 0 | C15: =+H15+K15+N15+Q15+T15 -> 0 | D15: =+C15-B15 -> 0 | E15: =+I15+L15+O15+R15+U15 -> 0 | F15: =+J15+M15+P15+S15+V15 -> 0
A16: psych. s 4 | B16: 0 | C16: =+H16+K16+N16+Q16+T16 -> 0 | D16: =+C16-B16 -> 0 | E16: =+I16+L16+O16+R16+U16 -> 0 | F16: =+J16+M16+P16+S16+V16 -> 0
A17: psychiatr 1 - 0,5 od 1.4 | B17: 0 | C17: =+H17+K17+N17+Q17+T17 -> 0 | D17: =+C17-B17 -> 0 | E17: =+I17+L17+O17+R17+U17 -> 0 | F17: =+J17+M17+P17+S17+V17 -> 0
A18: psychiatr 2 | B18: 0 | C18: =+H18+K18+N18+Q18+T18 -> 0 | D18: =+C18-B18 -> 0 | E18: =+I18+L18+O18+R18+U18 -> 0 | F18: =+J18+M18+P18+S18+V18 -> 0
A19: psycholog 1 - 0,5 | B19: 0 | C19: =+H19+K19+N19+Q19+T19 -> 0 | D19: =+C19-B19 -> 0 | E19: =+I19+L19+O19+R19+U19 -> 0 | F19: =+J19+M19+P19+S19+V19 -> 0
A20: psycholog 2 | B20: 0 | C20: =+H20+K20+N20+Q20+T20 -> 0 | D20: =+C20-B20 -> 0 | E20: =+I20+L20+O20+R20+U20 -> 0 | F20: =+J20+M20+P20+S20+V20 -> 0
A21: výnosy CDZ Žatec | B21: =SUM(B22:B29) -> 170000 | C21: =SUM(C22:C29) -> 99147 | D21: =SUM(D22:D29) -> -70853 | E21: =SUM(E22:E29) -> 0 | F21: =SUM(F22:F29) -> 0 | H21: =SUM(H22:H29) -> 0 | I21: =SUM(I22:I29) -> 0 | J21: =SUM(J22:J29) -> 0 | K21: =SUM(K22:K29) -> 0 | L21: =SUM(L22:L29) -> 0 | M21: =SUM(M22:M29) -> 0 | N21: =SUM(N22:N29) -> 0 | O21: =SUM(O22:O29) -> 0 | ... V21: =SUM(V22:V29) -> 0
A22: psych. s 1 - ZELENKOVÁ | B22: =200000*0.85 -> 170000 | C22: 99147 | D22: =+C22-B22 -> -70853 | E22: =+I22+L22+O22+R22+U22 -> 0 | F22: =+J22+M22+P22+S22+V22 -> 0
A23: psych. s 2 - Štěpánka … | B23: 0 | C23: =+H23+K23+N23+Q23+T23 -> 0 | D23: =+C23-B23 -> 0 | E23: =+I23+L23+O23+R23+U23 -> 0 | F23: =+J23+M23+P23+S23+V23 -> 0
A24: psych. s 3 - Bečvářová | B24: 0 | C24: =+H24+K24+N24+Q24+T24 -> 0 | D24: =+C24-B24 -> 0 | E24: =+I24+L24+O24+R24+U24 -> 0 | F24: =+J24+M24+P24+S24+V24 -> 0
A25: všeob. s 4 - Dušková | B25: 0 | C25: =+H25+K25+N25+Q25+T25 -> 0 | D25: =+C25-B25 -> 0 | E25: =+I25+L25+O25+R25+U25 -> 0 | F25: =+J25+M25+P25+S25+V25 -> 0
A26: psychiatr 1 - 0,5 od 1.4 | B26: 0 | C26: =+H26+K26+N26+Q26+T26 -> 0 | D26: =+C26-B26 -> 0 | E26: =+I26+L26+O26+R26+U26 -> 0 | F26: =+J26+M26+P26+S26+V26 -> 0
A27: psychiatr 2 | B27: 0 | C27: =+H27+K27+N27+Q27+T27 -> 0 | D27: =+C27-B27 -> 0 | E27: =+I27+L27+O27+R27+U27 -> 0 | F27: =+J27+M27+P27+S27+V27 -> 0
A28: psycholog 1 - 0,5 | B28: 0 | C28: =+H28+K28+N28+Q28+T28 -> 0 | D28: =+C28-B28 -> 0 | E28: =+I28+L28+O28+R28+U28 -> 0 | F28: =+J28+M28+P28+S28+V28 -> 0
A29: psycholog 2 | B29: 0 | C29: =+H29+K29+N29+Q29+T29 -> 0 | D29: =+C29-B29 -> 0 | E29: =+I29+L29+O29+R29+U29 -> 0 | F29: =+J29+M29+P29+S29+V29 -> 0
A30: výnosy CDZ Litoměřice | B30: =SUM(B31:B38) -> 0 | C30: =SUM(C31:C38) -> 0 | D30: =SUM(D31:D38) -> 0 | E30: =SUM(E31:E38) -> 0 | F30: =SUM(F31:F38) -> 0 | H30: =SUM(H31:H38) -> 0 | I30: =SUM(I31:I38) -> 0 | J30: =SUM(J31:J38) -> 0 | K30: =SUM(K31:K38) -> 0 | L30: =SUM(L31:L38) -> 0 | M30: =SUM(M31:M38) -> 0 | N30: =SUM(N31:N38) -> 0 | O30: =SUM(O31:O38) -> 0 | ... V30: =SUM(V31:V38) -> 0
A31: psych. s 1 - Štréblová 0,2 od 1.3 od 5 celý | B31: 0 | C31: =+H31+K31+N31+Q31+T31 -> 0 | D31: =+C31-B31 -> 0 | E31: =+I31+L31+O31+R31+U31 -> 0 | F31: =+J31+M31+P31+S31+V31 -> 0
A32: psych. s 2 | B32: 0 | C32: =+H32+K32+N32+Q32+T32 -> 0 | D32: =+C32-B32 -> 0 | E32: =+I32+L32+O32+R32+U32 -> 0 | F32: =+J32+M32+P32+S32+V32 -> 0
A33: psych. s 3 | B33: 0 | C33: =+H33+K33+N33+Q33+T33 -> 0 | D33: =+C33-B33 -> 0 | E33: =+I33+L33+O33+R33+U33 -> 0 | F33: =+J33+M33+P33+S33+V33 -> 0
A34: psych. s 4 | B34: 0 | C34: =+H34+K34+N34+Q34+T34 -> 0 | D34: =+C34-B34 -> 0 | E34: =+I34+L34+O34+R34+U34 -> 0 | F34: =+J34+M34+P34+S34+V34 -> 0
A35: psychiatr 1 - 0,5 | B35: 0 | C35: =+H35+K35+N35+Q35+T35 -> 0 | D35: =+C35-B35 -> 0 | E35: =+I35+L35+O35+R35+U35 -> 0 | F35: =+J35+M35+P35+S35+V35 -> 0
A36: psychiatr 2 | B36: 0 | C36: =+H36+K36+N36+Q36+T36 -> 0 | D36: =+C36-B36 -> 0 | E36: =+I36+L36+O36+R36+U36 -> 0 | F36: =+J36+M36+P36+S36+V36 -> 0
A37: psycholog 1 - 0,5 | B37: 0 | C37: =+H37+K37+N37+Q37+T37 -> 0 | D37: =+C37-B37 -> 0 | E37: =+I37+L37+O37+R37+U37 -> 0 | F37: =+J37+M37+P37+S37+V37 -> 0
A38: psycholog 2 | B38: 0 | C38: =+H38+K38+N38+Q38+T38 -> 0 | D38: =+C38-B38 -> 0 | E38: =+I38+L38+O38+R38+U38 -> 0 | F38: =+J38+M38+P38+S38+V38 -> 0
A39: výnosy TDZ Děčín | B39: =SUM(B40:B41) -> 170000 | C39: =SUM(C40:C41) -> 43249 | D39: =SUM(D40:D41) -> -126751 | E39: =SUM(E40:E41) -> 0 | F39: =SUM(F40:F41) -> 0 | H39: =SUM(H40:H41) -> 0 | I39: =SUM(I40:I41) -> 0 | J39: =SUM(J40:J41) -> 0 | K39: =SUM(K40:K41) -> 0 | L39: =SUM(L40:L41) -> 0 | M39: =SUM(M40:M41) -> 0 | N39: =SUM(N40:N41) -> 0 | O39: =SUM(O40:O41) -> 0 | ... V39: =SUM(V40:V41) -> 0
A40: psych. s 1 - Jirásková | B40: =200000*0.85 -> 170000 | C40: 43249 | D40: =+C40-B40 -> -126751 | E40: =+I40+L40+O40+R40+U40 -> 0 | F40: =+J40+M40+P40+S40+V40 -> 0
...

Sheet březen 2025
A1: VÝNOSY | H1: týden 1 (zpravidla dělený s předchozím měsícem) | K1: týden 2 | N1: týden 3 | Q1: týden 4 | T1: týden 5 (zpravidla dělený s následujícím měsícem)
A2: Středisko/pracovník | B2: plán měsíce | C2: skutečnost měsíce | D2: rozdíl | E2: počet intervencí | F2: odpracováno hod. | H2: výkony /týden | I2: počet intervencí | J2: odpracováno hod. | K2: výkony /týden | L2: počet intervencí | M2: odpracováno hod. | N2: výkony /týden | O2: počet intervencí | P2: odpracováno hod. | Q2: výkony /týden | R2: počet intervencí | S2: odpracováno hod. | T2: výkony /týden | U2: počet intervencí | V2: odpracováno hod.
A3: výnosy CDZ Ústí | B3: =SUM(B4:B11) -> 1535000 | C3: =SUM(C4:C11) -> 1117149.8 | D3: =SUM(D4:D11) -> -417850.16 | E3: =SUM(E4:E11) -> 921 | F3: =SUM(F4:F11) -> 57.725694 | H3: =SUM(H4:H11) -> 225912.24 | I3: =SUM(I4:I11) -> 187 | J3: =SUM(J4:J11) -> 11.319444 | K3: =SUM(K4:K11) -> 270351 | L3: =SUM(L4:L11) -> 217 | M3: =SUM(M4:M11) -> 13.986111 | N3: =SUM(N4:N11) -> 272258.28 | O3: =SUM(O4:O11) -> 233 | ... V3: =SUM(V4:V11) -> 3.6944444
A4: psych. s. 1 - NÁGLOVÁ | B4: 200000 | C4: =+H4+K4+N4+Q4+T4 -> 208010.16 | D4: =+C4-B4 -> 8010.16 | E4: =+I4+L4+O4+R4+U4 -> 215 | F4: =+J4+M4+P4+S4+V4 -> 12.770833 | H4: 46651.68 | I4: 52 | J4: 2.8888889 | K4: 43586.64 | L4: 42 | M4: 2.7083333 | N4: 45339.48 | O4: 50 | P4: 2.8472222 | Q4: 59229.36 | R4: 56 | S4: 3.5416667 | T4: 13203 | U4: 15 | V4: 0.78472222
A5: psych. s. 2 - HAJASOVÁ | B5: 200000 | C5: =+H5+K5+N5+Q5+T5 -> 150631.92 | D5: =+C5-B5 -> -49368.08 | E5: =+I5+L5+O5+R5+U5 -> 126 | F5: =+J5+M5+P5+S5+V5 -> 9.25 | K5: 50150.88 | L5: 41 | M5: 3.0416667 | N5: 44215.2 | O5: 39 | P5: 2.75 | Q5: 46954.08 | R5: 39 | S5: 2.875 | T5: 9311.76 | U5: 7 | V5: 0.58333333
A6: psych. s. 3 - KAŠPÁRKOVÁ/Pekárová | B6: 200000 | C6: =+H6+K6+N6+Q6+T6 -> 187573.32 | D6: =+C6-B6 -> -12426.68 | E6: =+I6+L6+O6+R6+U6 -> 175 | F6: =+J6+M6+P6+S6+V6 -> 11.642361 | H6: 51904.8 | I6: 48 | J6: 3.1805556 | K6: 45433.44 | L6: 44 | M6: 2.8194444 | N6: 44580.24 | O6: 44 | P6: 2.7743056 | Q6: 36343.08 | R6: 30 | S6: 2.2847222 | T6: 9311.76 | U6: 9 | V6: 0.58333333
A7: psych. s. 4 - Pátková | B7: 170000 | C7: =+H7+K7+N7+Q7+T7 -> 18856.8 | D7: =+C7-B7 -> -151143.2 | E7: =+I7+L7+O7+R7+U7 -> 15 | F7: =+J7+M7+P7+S7+V7 -> 1.25 | N7: 6285.6 | O7: 5 | P7: 0.41666667 | Q7: 12571.2 | R7: 10 | S7: 0.83333333
A8: psychiatr - GÁBEL 0,2 | B8: =450000*0.2 -> 90000 | C8: =+H8+K8+N8+Q8+T8 -> 4887 | D8: =+C8-B8 -> -85113 | E8: =+I8+L8+O8+R8+U8 -> 25 | F8: =+J8+M8+P8+S8+V8 -> 0.17361111 | H8: 1368.36 | I8: 7 | J8: 0.048611111 | K8: 1172.88 | L8: 6 | M8: 0.041666667 | N8: 1172.88 | O8: 6 | P8: 0.041666667 | Q8: 1172.88 | R8: 6 | S8: 0.041666667
A9: psychiatr - PFEIFFER 0,5 | B9: =450000*0.5 -> 225000 | C9: =+H9+K9+N9+Q9+T9 -> 223206.84 | D9: =+C9-B9 -> -1793.16 | E9: =+I9+L9+O9+R9+U9 -> 184 | F9: =+J9+M9+P9+S9+V9 -> 9.0694444 | H9: 50715.72 | I9: 41 | J9: 2.0347222 | K9: 56906.28 | L9: 42 | M9: 2.3333333 | N9: 53327.16 | O9: 44 | P9: 2.1597222 | Q9: 45610.56 | R9: 39 | S9: 1.875 | T9: 16647.12 | U9: 18 | V9: 0.66666667
A10: psychiatr - Dr. Suchánková 1,0 | B10: =450000 -> 450000 | C10: =+H10+K10+N10+Q10+T10 -> 323983.8 | D10: =+C10-B10 -> -126016.2 | E10: =+I10+L10+O10+R10+U10 -> 181 | F10: =+J10+M10+P10+S10+V10 -> 13.569444 | H10: 75271.68 | I10: 39 | J10: 3.1666667 | K10: 73100.88 | L10: 42 | M10: 3.0416667 | N10: 77337.72 | O10: 45 | P10: 3.2291667 | Q10: 72552.24 | R10: 44 | S10: 3.0555556 | T10: 25721.28 | U10: 11 | V10: 1.0763889
A11: psycholog 2 - Lichtenbergová | B11: 0 | C11: =+H11+K11+N11+Q11+T11 -> 0 | D11: =+C11-B11 -> 0 | E11: =+I11+L11+O11+R11+U11 -> 0 | F11: =+J11+M11+P11+S11+V11 -> 0
A12: výnosy CDZ Chomutov | B12: =SUM(B13:B20) -> 170000 | C12: =SUM(C13:C20) -> 106181.04 | D12: =SUM(D13:D20) -> -63818.96 | E12: =SUM(E13:E20) -> 153 | F12: =SUM(F13:F20) -> 7.7569444 | H12: =SUM(H13:H20) -> 26473.72 | I12: =SUM(I13:I20) -> 36 | J12: =SUM(J13:J20) -> 1.9340278 | K12: =SUM(K13:K20) -> 26236.56 | L12: =SUM(L13:L20) -> 36 | M12: =SUM(M13:M20) -> 1.9166667 | N12: =SUM(N13:N20) -> 24430.42 | O12: =SUM(O13:O20) -> 34 | ... V12: =SUM(V13:V20) -> 0.32638889
A13: psych. s 1 - Blažková | B13: =200000*0.85 -> 170000 | C13: =+H13+K13+N13+Q13+T13 -> 106181.04 | D13: =+C13-B13 -> -63818.96 | E13: =+I13+L13+O13+R13+U13 -> 153 | F13: =+J13+M13+P13+S13+V13 -> 7.7569444 | H13: 26473.72 | I13: 36 | J13: 1.9340278 | K13: 26236.56 | L13: 36 | M13: 1.9166667 | N13: 24430.42 | O13: 34 | P13: 1.7847222 | Q13: 24572.52 | R13: 39 | S13: 1.7951389 | T13: 4467.82 | U13: 8 | V13: 0.32638889
A14: psych. s 2 | B14: 0 | C14: =+H14+K14+N14+Q14+T14 -> 0 | D14: =+C14-B14 -> 0 | E14: =+I14+L14+O14+R14+U14 -> 0 | F14: =+J14+M14+P14+S14+V14 -> 0
A15: psych. s 3 | B15: 0 | C15: =+H15+K15+N15+Q15+T15 -> 0 | D15: =+C15-B15 -> 0 | E15: =+I15+L15+O15+R15+U15 -> 0 | F15: =+J15+M15+P15+S15+V15 -> 0
A16: psych. s 4 | B16: 0 | C16: =+H16+K16+N16+Q16+T16 -> 0 | D16: =+C16-B16 -> 0 | E16: =+I16+L16+O16+R16+U16 -> 0 | F16: =+J16+M16+P16+S16+V16 -> 0
A17: psychiatr 1 - 0,5 od 1.4 | B17: 0 | C17: =+H17+K17+N17+Q17+T17 -> 0 | D17: =+C17-B17 -> 0 | E17: =+I17+L17+O17+R17+U17 -> 0 | F17: =+J17+M17+P17+S17+V17 -> 0
A18: psychiatr 2 | B18: 0 | C18: =+H18+K18+N18+Q18+T18 -> 0 | D18: =+C18-B18 -> 0 | E18: =+I18+L18+O18+R18+U18 -> 0 | F18: =+J18+M18+P18+S18+V18 -> 0
A19: psycholog 1 - 0,5 | B19: 0 | C19: =+H19+K19+N19+Q19+T19 -> 0 | D19: =+C19-B19 -> 0 | E19: =+I19+L19+O19+R19+U19 -> 0 | F19: =+J19+M19+P19+S19+V19 -> 0
A20: psycholog 2 | B20: 0 | C20: =+H20+K20+N20+Q20+T20 -> 0 | D20: =+C20-B20 -> 0 | E20: =+I20+L20+O20+R20+U20 -> 0 | F20: =+J20+M20+P20+S20+V20 -> 0
A21: výnosy CDZ Žatec | B21: =SUM(B22:B29) -> 170000 | C21: =SUM(C22:C29) -> 109698.26 | D21: =SUM(D22:D29) -> -60301.74 | E21: =SUM(E22:E29) -> 118 | F21: =SUM(F22:F29) -> 8.0138889 | H21: =SUM(H22:H29) -> 18916.94 | I21: =SUM(I22:I29) -> 23 | J21: =SUM(J22:J29) -> 1.3819444 | K21: =SUM(K22:K29) -> 28612.08 | L21: =SUM(L22:L29) -> 27 | M21: =SUM(M22:M29) -> 2.0902778 | N21: =SUM(N22:N29) -> 28518 | O21: =SUM(O22:O29) -> 33 | ... V21: =SUM(V22:V29) -> 0.40972222
A22: psych. s 1 - ZELENKOVÁ | B22: =200000*0.85 -> 170000 | C22: =+H22+K22+N22+Q22+T22 -> 109698.26 | D22: =+C22-B22 -> -60301.74 | E22: =+I22+L22+O22+R22+U22 -> 118 | F22: =+J22+M22+P22+S22+V22 -> 8.0138889 | H22: 18916.94 | I22: 23 | J22: 1.3819444 | K22: 28612.08 | L22: 27 | M22: 2.0902778 | N22: 28518 | O22: 33 | P22: 2.0833333 | Q22: 28042.7 | R22: 28 | S22: 2.0486111 | T22: 5608.54 | U22: 7 | V22: 0.40972222
A23: psych. s 2 - Vondráčková | B23: 0 | C23: =+H23+K23+N23+Q23+T23 -> 0 | D23: =+C23-B23 -> 0 | E23: =+I23+L23+O23+R23+U23 -> 0 | F23: =+J23+M23+P23+S23+V23 -> 0
A24: psych. s 3 - Nováková | B24: 0 | C24: =+H24+K24+N24+Q24+T24 -> 0 | D24: =+C24-B24 -> 0 | E24: =+I24+L24+O24+R24+U24 -> 0 | F24: =+J24+M24+P24+S24+V24 -> 0
A25: všeob. s 4 - Dušková | B25: 0 | C25: =+H25+K25+N25+Q25+T25 -> 0 | D25: =+C25-B25 -> 0 | E25: =+I25+L25+O25+R25+U25 -> 0 | F25: =+J25+M25+P25+S25+V25 -> 0
A26: psychiatr 1 - 0,5 od 1.4 | B26: 0 | C26: =+H26+K26+N26+Q26+T26 -> 0 | D26: =+C26-B26 -> 0 | E26: =+I26+L26+O26+R26+U26 -> 0 | F26: =+J26+M26+P26+S26+V26 -> 0
A27: psychiatr 2 | B27: 0 | C27: =+H27+K27+N27+Q27+T27 -> 0 | D27: =+C27-B27 -> 0 | E27: =+I27+L27+O27+R27+U27 -> 0 | F27: =+J27+M27+P27+S27+V27 -> 0
A28: psycholog 1 - 0,5 | B28: 0 | C28: =+H28+K28+N28+Q28+T28 -> 0 | D28: =+C28-B28 -> 0 | E28: =+I28+L28+O28+R28+U28 -> 0 | F28: =+J28+M28+P28+S28+V28 -> 0
A29: psycholog 2 | B29: 0 | C29: =+H29+K29+N29+Q29+T29 -> 0 | D29: =+C29-B29 -> 0 | E29: =+I29+L29+O29+R29+U29 -> 0 | F29: =+J29+M29+P29+S29+V29 -> 0
A30: výnosy CDZ Litoměřice | B30: =SUM(B31:B38) -> 34000 | C30: =SUM(C31:C38) -> 21388.5 | D30: =SUM(D31:D38) -> -12611.5 | E30: =SUM(E31:E38) -> 22 | F30: =SUM(F31:F38) -> 1.75 | H30: =SUM(H31:H38) -> 5275.83 | I30: =SUM(I31:I38) -> 6 | J30: =SUM(J31:J38) -> 0.47916667 | K30: =SUM(K31:K38) -> 5133.24 | L30: =SUM(L31:L38) -> 5 | M30: =SUM(M31:M38) -> 0.375 | N30: =SUM(N31:N38) -> 2851.8 | O30: =SUM(O31:O38) -> 3 | ... V30: =SUM(V31:V38) -> 0
A31: psych. s 1 - Štréblová 0,2 od 1.3 od 5 celý | B31: =200000*0.2*0.85 -> 34000 | C31: =+H31+K31+N31+Q31+T31 -> 21388.5 | D31: =+C31-B31 -> -12611.5 | E31: =+I31+L31+O31+R31+U31 -> 22 | F31: =+J31+M31+P31+S31+V31 -> 1.75 | H31: 5275.83 | I31: 6 | J31: 0.47916667 | K31: 5133.24 | L31: 5 | M31: 0.375 | N31: 2851.8 | O31: 3 | P31: 0.20833333 | Q31: 8127.63 | R31: 8 | S31: 0.6875
A32: psych. s 2 | B32: 0 | C32: =+H32+K32+N32+Q32+T32 -> 0 | D32: =+C32-B32 -> 0 | E32: =+I32+L32+O32+R32+U32 -> 0 | F32: =+J32+M32+P32+S32+V32 -> 0
A33: psych. s 3 | B33: 0 | C33: =+H33+K33+N33+Q33+T33 -> 0 | D33: =+C33-B33 -> 0 | E33: =+I33+L33+O33+R33+U33 -> 0 | F33: =+J33+M33+P33+S33+V33 -> 0
A34: psych. s 4 | B34: 0 | C34: =+H34+K34+N34+Q34+T34 -> 0 | D34: =+C34-B34 -> 0 | E34: =+I34+L34+O34+R34+U34 -> 0 | F34: =+J34+M34+P34+S34+V34 -> 0
A35: psychiatr 1 - 0,5 | B35: 0 | C35: =+H35+K35+N35+Q35+T35 -> 0 | D35: =+C35-B35 -> 0 | E35: =+I35+L35+O35+R35+U35 -> 0 | F35: =+J35+M35+P35+S35+V35 -> 0
A36: psychiatr 2 | B36: 0 | C36: =+H36+K36+N36+Q36+T36 -> 0 | D36: =+C36-B36 -> 0 | E36: =+I36+L36+O36+R36+U36 -> 0 | F36: =+J36+M36+P36+S36+V36 -> 0
A37: psycholog 1 - 0,5 | B37: 0 | C37: =+H37+K37+N37+Q37+T37 -> 0 | D37: =+C37-B37 -> 0 | E37: =+I37+L37+O37+R37+U37 -> 0 | F37: =+J37+M37+P37+S37+V37 -> 0
A38: psycholog 2 | B38: 0 | C38: =+H38+K38+N38+Q38+T38 -> 0 | D38: =+C38-B38 -> 0 | E38: =+I38+L38+O38+R38+U38 -> 0 | F38: =+J38+M38+P38+S38+V38 -> 0
A39: výnosy TDZ Děčín | B39: =SUM(B40:B41) -> 170000 | C39: =SUM(C40:C41) -> 87397.38 | D39: =SUM(D40:D41) -> -82602.62 | E39: =SUM(E40:E41) -> 108 | F39: =SUM(F40:F41) -> 6.3854167 | H39: =SUM(H40:H41) -> 23382.8 | I39: =SUM(I40:I41) -> 27 | J39: =SUM(J40:J41) -> 1.7083333 | K39: =SUM(K40:K41) -> 23096.64 | L39: =SUM(L40:L41) -> 28 | M39: =SUM(M40:M41) -> 1.6875 | N39: =SUM(N40:N41) -> 22810.48 | O39: =SUM(O40:O41) -> 30 | ... V39: =SUM(V40:V41) -> 0
A40: psych. s 1 - Jirásková | B40: =200000*0.85 -> 170000 | C40: =+H40+K40+N40+Q40+T40 -> 87397.38 | D40: =+C40-B40 -> -82602.62 | E40: =+I40+L40+O40+R40+U40 -> 108 | F40: =+J40+M40+P40+S40+V40 -> 6.3854167 | H40: 23382.8 | I40: 27 | J40: 1.7083333 | K40: 23096.64 | L40: 28 | M40: 1.6875 | N40: 22810.48 | O40: 30 | P40: 1.6666667 | Q40: 18107.46 | R40: 23 | S40: 1.3229167
...

Sheet duben 2025
A1: VÝNOSY | H1: týden 1 (zpravidla dělený s předchozím měsícem) | K1: týden 2 | N1: týden 3 | Q1: týden 4 | T1: týden 5 (zpravidla dělený s následujícím měsícem)
A2: Středisko/pracovník | B2: plán měsíce | C2: skutečnost měsíce | D2: rozdíl | E2: počet intervencí | F2: odpracováno hod. | H2: výkony /týden | I2: počet intervencí | J2: odpracováno hod. | K2: výkony /týden | L2: počet intervencí | M2: odpracováno hod. | N2: výkony /týden | O2: počet intervencí | P2: odpracováno hod. | Q2: výkony /týden | R2: počet intervencí | S2: odpracováno hod. | T2: výkony /týden | U2: počet intervencí | V2: odpracováno hod.
A3: výnosy CDZ Ústí | B3: =SUM(B4:B11) -> 1365000 | C3: =SUM(C4:C11) -> 926865.96 | D3: =SUM(D4:D11) -> -438134.04 | E3: =SUM(E4:E11) -> 883 | F3: =SUM(F4:F11) -> 50.874306 | H3: =SUM(H4:H11) -> 201952.44 | I3: =SUM(I4:I11) -> 197 | J3: =SUM(J4:J11) -> 10.819444 | K3: =SUM(K4:K11) -> 194797.44 | L3: =SUM(L4:L11) -> 175 | M3: =SUM(M4:M11) -> 9.9895833 | N3: =SUM(N4:N11) -> 202698.72 | O3: =SUM(O4:O11) -> 193 | ... V3: =SUM(V4:V11) -> 7.4861111
A4: psych. s. 1 - NÁGLOVÁ | B4: 200000 | C4: =+H4+K4+N4+Q4+T4 -> 179540.28 | D4: =+C4-B4 -> -20459.72 | E4: =+I4+L4+O4+R4+U4 -> 191 | F4: =+J4+M4+P4+S4+V4 -> 11.121528 | H4: 32374.08 | I4: 35 | J4: 2.0555556 | K4: 40807.8 | L4: 43 | M4: 2.5243056 | N4: 38727.72 | O4: 36 | P4: 2.375 | Q4: 40599.36 | R4: 42 | S4: 2.4652778 | T4: 27031.32 | U4: 35 | V4: 1.7013889
A5: psych. s. 2 - HAJASOVÁ | B5: 200000 | C5: =+H5+K5+N5+Q5+T5 -> 137392.2 | D5: =+C5-B5 -> -62607.8 | E5: =+I5+L5+O5+R5+U5 -> 113 | F5: =+J5+M5+P5+S5+V5 -> 8.7569444 | H5: 31536 | I5: 24 | J5: 2 | K5: 34193.88 | L5: 28 | M5: 2.1875 | N5: 20835.36 | O5: 18 | P5: 1.3472222 | Q5: 30488.4 | R5: 26 | S5: 1.9305556 | T5: 20338.56 | U5: 17 | V5: 1.2916667
A6: psych. s. 3 - KAŠPÁRKOVÁ/Pekárová | B6: 200000 | C6: =+H6+K6+N6+Q6+T6 -> 99048.12 | D6: =+C6-B6 -> -100951.88 | E6: =+I6+L6+O6+R6+U6 -> 101 | F6: =+J6+M6+P6+S6+V6 -> 8.2145833 | H6: 30973.32 | I6: 33 | J6: 1.9513889 | N6: 32910.84 | O6: 40 | P6: 2.0798611 | Q6: 22592.76 | R6: 18 | S6: 3.35 | T6: 12571.2 | U6: 10 | V6: 0.83333333
A7: psych. s. 4 - | B7: 0 | C7: =+H7+K7+N7+Q7+T7 -> 0 | D7: =+C7-B7 -> 0 | E7: =+I7+L7+O7+R7+U7 -> 0 | F7: =+J7+M7+P7+S7+V7 -> 0
A8: psychiatr - GÁBEL 0,2 | B8: =450000*0.2 -> 90000 | C8: =+H8+K8+N8+Q8+T8 -> 4887 | D8: =+C8-B8 -> -85113 | E8: =+I8+L8+O8+R8+U8 -> 25 | F8: =+J8+M8+P8+S8+V8 -> 0.17361111 | H8: 1368.36 | I8: 7 | J8: 0.048611111 | K8: 1172.88 | L8: 6 | M8: 0.041666667 | N8: 1172.88 | O8: 6 | P8: 0.041666667 | Q8: 1172.88 | R8: 6 | S8: 0.041666667 | T8: 0
A9: psychiatr - PFEIFFER 0,5 | B9: =450000*0.5 -> 225000 | C9: =+H9+K9+N9+Q9+T9 -> 127490.76 | D9: =+C9-B9 -> -97509.24 | E9: =+I9+L9+O9+R9+U9 -> 150 | F9: =+J9+M9+P9+S9+V9 -> 5.2569444 | H9: 22904.64 | I9: 31 | J9: 0.95833333 | K9: 27547.56 | L9: 31 | M9: 1.125 | N9: 28045.44 | O9: 31 | P9: 1.1458333 | Q9: 15954.84 | R9: 22 | S9: 0.65277778 | T9: 33038.28 | U9: 35 | V9: 1.375
A10: psychiatr - Dr. Suchánková 1,0 | B10: =450000 -> 450000 | C10: =+H10+K10+N10+Q10+T10 -> 378507.6 | D10: =+C10-B10 -> -71492.4 | E10: =+I10+L10+O10+R10+U10 -> 303 | F10: =+J10+M10+P10+S10+V10 -> 17.350694 | H10: 82796.04 | I10: 67 | J10: 3.8055556 | K10: 91075.32 | L10: 67 | M10: 4.1111111 | N10: 81006.48 | O10: 62 | P10: 3.6805556 | Q10: 74068.56 | R10: 66 | S10: 3.46875 | T10: 49561.2 | U10: 41 | V10: 2.2847222
A11: psycholog 2 - Lichtenbergová | B11: 0 | C11: =+H11+K11+N11+Q11+T11 -> 0 | D11: =+C11-B11 -> 0 | E11: =+I11+L11+O11+R11+U11 -> 0 | F11: =+J11+M11+P11+S11+V11 -> 0
A12: výnosy CDZ Chomutov | B12: =SUM(B13:B20) -> 340000 | C12: =SUM(C13:C20) -> 159456.78 | D12: =SUM(D13:D20) -> -180543.22 | E12: =SUM(E13:E20) -> 211 | F12: =SUM(F13:F20) -> 11.649306 | H12: =SUM(H13:H20) -> 33270.02 | I12: =SUM(I13:I20) -> 42 | J12: =SUM(J13:J20) -> 2.4305556 | K12: =SUM(K13:K20) -> 31511.9 | L12: =SUM(L13:L20) -> 40 | M12: =SUM(M13:M20) -> 2.3020833 | N12: =SUM(N13:N20) -> 38592.4 | O12: =SUM(O13:O20) -> 49 | ... V12: =SUM(V13:V20) -> 2.09375
A13: psych. s 1 - Blažková | B13: =200000*0.85 -> 170000 | C13: =+H13+K13+N13+Q13+T13 -> 91110.6 | D13: =+C13-B13 -> -78889.4 | E13: =+I13+L13+O13+R13+U13 -> 132 | F13: =+J13+M13+P13+S13+V13 -> 6.65625 | H13: 20151.74 | I13: 30 | J13: 1.4722222 | K13: 23526.86 | L13: 29 | M13: 1.71875 | N13: 19770.52 | O13: 28 | P13: 1.4444444 | Q13: 13545.56 | R13: 19 | S13: 0.98958333 | T13: 14115.92 | U13: 26 | V13: 1.03125
A14: psych. s 2 - Pátková | B14: =200000*0.85 -> 170000 | C14: =+H14+K14+N14+Q14+T14 -> 68346.18 | D14: =+C14-B14 -> -101653.82 | E14: =+I14+L14+O14+R14+U14 -> 79 | F14: =+J14+M14+P14+S14+V14 -> 4.9930556 | H14: 13118.28 | I14: 12 | J14: 0.95833333 | K14: 7985.04 | L14: 11 | M14: 0.58333333 | N14: 18821.88 | O14: 21 | P14: 1.375 | Q14: 13878.76 | R14: 17 | S14: 1.0138889 | T14: 14542.22 | U14: 18 | V14: 1.0625
A15: psych. s 3 | B15: 0 | C15: =+H15+K15+N15+Q15+T15 -> 0 | D15: =+C15-B15 -> 0 | E15: =+I15+L15+O15+R15+U15 -> 0 | F15: =+J15+M15+P15+S15+V15 -> 0
A16: psych. s 4 | B16: 0 | C16: =+H16+K16+N16+Q16+T16 -> 0 | D16: =+C16-B16 -> 0 | E16: =+I16+L16+O16+R16+U16 -> 0 | F16: =+J16+M16+P16+S16+V16 -> 0
A17: psychiatr 1 - 0,5 od ?? | B17: 0 | C17: =+H17+K17+N17+Q17+T17 -> 0 | D17: =+C17-B17 -> 0 | E17: =+I17+L17+O17+R17+U17 -> 0 | F17: =+J17+M17+P17+S17+V17 -> 0
A18: psychiatr 2 | B18: 0 | C18: =+H18+K18+N18+Q18+T18 -> 0 | D18: =+C18-B18 -> 0 | E18: =+I18+L18+O18+R18+U18 -> 0 | F18: =+J18+M18+P18+S18+V18 -> 0
A19: psycholog 1 - 0,5 | B19: 0 | C19: =+H19+K19+N19+Q19+T19 -> 0 | D19: =+C19-B19 -> 0 | E19: =+I19+L19+O19+R19+U19 -> 0 | F19: =+J19+M19+P19+S19+V19 -> 0
A20: psycholog 2 | B20: 0 | C20: =+H20+K20+N20+Q20+T20 -> 0 | D20: =+C20-B20 -> 0 | E20: =+I20+L20+O20+R20+U20 -> 0 | F20: =+J20+M20+P20+S20+V20 -> 0
A21: výnosy CDZ Žatec | B21: =SUM(B22:B29) -> 170000 | C21: =SUM(C22:C29) -> 109409.16 | D21: =SUM(D22:D29) -> -60590.84 | E21: =SUM(E22:E29) -> 123 | F21: =SUM(F22:F29) -> 7.9930556 | H21: =SUM(H22:H29) -> 23192.68 | I21: =SUM(I22:I29) -> 23 | J21: =SUM(J22:J29) -> 1.6944444 | K21: =SUM(K22:K29) -> 27661.48 | L21: =SUM(L22:L29) -> 32 | M21: =SUM(M22:M29) -> 2.0208333 | N21: =SUM(N22:N29) -> 18060.42 | O21: =SUM(O22:O29) -> 19 | ... V21: =SUM(V22:V29) -> 1.3125
A22: psych. s 1 - ZELENKOVÁ | B22: =200000*0.85 -> 170000 | C22: =+H22+K22+N22+Q22+T22 -> 109409.16 | D22: =+C22-B22 -> -60590.84 | E22: =+I22+L22+O22+R22+U22 -> 123 | F22: =+J22+M22+P22+S22+V22 -> 7.9930556 | H22: 23192.68 | I22: 23 | J22: 1.6944444 | K22: 27661.48 | L22: 32 | M22: 2.0208333 | N22: 18060.42 | O22: 19 | P22: 1.3194444 | Q22: 22528.24 | R22: 22 | S22: 1.6458333 | T22: 17966.34 | U22: 27 | V22: 1.3125
A23: psych. s 2 - Vondráčková | B23: 0 | C23: =+H23+K23+N23+Q23+T23 -> 0 | D23: =+C23-B23 -> 0 | E23: =+I23+L23+O23+R23+U23 -> 0 | F23: =+J23+M23+P23+S23+V23 -> 0
A24: psych. s 3 - Nováková | B24: 0 | C24: =+H24+K24+N24+Q24+T24 -> 0 | D24: =+C24-B24 -> 0 | E24: =+I24+L24+O24+R24+U24 -> 0 | F24: =+J24+M24+P24+S24+V24 -> 0
A25: všeob. s 4 - Dušková | B25: 0 | C25: =+H25+K25+N25+Q25+T25 -> 0 | D25: =+C25-B25 -> 0 | E25: =+I25+L25+O25+R25+U25 -> 0 | F25: =+J25+M25+P25+S25+V25 -> 0
A26: psychiatr 1 - 0,5 od 1.4 | B26: 0 | C26: =+H26+K26+N26+Q26+T26 -> 0 | D26: =+C26-B26 -> 0 | E26: =+I26+L26+O26+R26+U26 -> 0 | F26: =+J26+M26+P26+S26+V26 -> 0
A27: psychiatr 2 | B27: 0 | C27: =+H27+K27+N27+Q27+T27 -> 0 | D27: =+C27-B27 -> 0 | E27: =+I27+L27+O27+R27+U27 -> 0 | F27: =+J27+M27+P27+S27+V27 -> 0
A28: psycholog 1 - 0,5 | B28: 0 | C28: =+H28+K28+N28+Q28+T28 -> 0 | D28: =+C28-B28 -> 0 | E28: =+I28+L28+O28+R28+U28 -> 0 | F28: =+J28+M28+P28+S28+V28 -> 0
A29: psycholog 2 | B29: 0 | C29: =+H29+K29+N29+Q29+T29 -> 0 | D29: =+C29-B29 -> 0 | E29: =+I29+L29+O29+R29+U29 -> 0 | F29: =+J29+M29+P29+S29+V29 -> 0
A30: výnosy CDZ Litoměřice | B30: =SUM(B31:B38) -> 34000 | C30: =SUM(C31:C38) -> 26756.94 | D30: =SUM(D31:D38) -> -7243.06 | E30: =SUM(E31:E38) -> 31 | F30: =SUM(F31:F38) -> 1.9548611 | H30: =SUM(H31:H38) -> 4561.9 | I30: =SUM(I31:I38) -> 6 | J30: =SUM(J31:J38) -> 0.33333333 | K30: =SUM(K31:K38) -> 5133.24 | L30: =SUM(L31:L38) -> 5 | M30: =SUM(M31:M38) -> 0.375 | N30: =SUM(N31:N38) -> 4371.78 | O30: =SUM(O31:O38) -> 6 | ... V30: =SUM(V31:V38) -> 0.60416667
A31: psych. s 1 - Štréblová 0,2 od 1.3 od 5 celý | B31: =200000*0.2*0.85 -> 34000 | C31: =+H31+K31+N31+Q31+T31 -> 26756.94 | D31: =+C31-B31 -> -7243.06 | E31: =+I31+L31+O31+R31+U31 -> 31 | F31: =+J31+M31+P31+S31+V31 -> 1.9548611 | H31: 4561.9 | I31: 6 | J31: 0.33333333 | K31: 5133.24 | L31: 5 | M31: 0.375 | N31: 4371.78 | O31: 6 | P31: 0.31944444 | Q31: 4419.8 | R31: 6 | S31: 0.32291667 | T31: 8270.22 | U31: 8 | V31: 0.60416667
A32: psych. s 2 | B32: 0 | C32: =+H32+K32+N32+Q32+T32 -> 0 | D32: =+C32-B32 -> 0 | E32: =+I32+L32+O32+R32+U32 -> 0 | F32: =+J32+M32+P32+S32+V32 -> 0
A33: ho | B33: 0 | C33: =+H33+K33+N33+Q33+T33 -> 0 | D33: =+C33-B33 -> 0 | E33: =+I33+L33+O33+R33+U33 -> 0 | F33: =+J33+M33+P33+S33+V33 -> 0
A34: psych. s 4 | B34: 0 | C34: =+H34+K34+N34+Q34+T34 -> 0 | D34: =+C34-B34 -> 0 | E34: =+I34+L34+O34+R34+U34 -> 0 | F34: =+J34+M34+P34+S34+V34 -> 0
A35: psychiatr 1 - 0,5 | B35: 0 | C35: =+H35+K35+N35+Q35+T35 -> 0 | D35: =+C35-B35 -> 0 | E35: =+I35+L35+O35+R35+U35 -> 0 | F35: =+J35+M35+P35+S35+V35 -> 0
A36: psychiatr 2 | B36: 0 | C36: =+H36+K36+N36+Q36+T36 -> 0 | D36: =+C36-B36 -> 0 | E36: =+I36+L36+O36+R36+U36 -> 0 | F36: =+J36+M36+P36+S36+V36 -> 0
A37: psycholog 1 - 0,5 | B37: 0 | C37: =+H37+K37+N37+Q37+T37 -> 0 | D37: =+C37-B37 -> 0 | E37: =+I37+L37+O37+R37+U37 -> 0 | F37: =+J37+M37+P37+S37+V37 -> 0
A38: psycholog 2 | B38: 0 | C38: =+H38+K38+N38+Q38+T38 -> 0 | D38: =+C38-B38 -> 0 | E38: =+I38+L38+O38+R38+U38 -> 0 | F38: =+J38+M38+P38+S38+V38 -> 0
A39: výnosy TDZ Děčín | B39: =SUM(B40:B41) -> 170000 | C39: =SUM(C40:C41) -> 37262.54 | D39: =SUM(D40:D41) -> -132737.46 | E39: =SUM(E40:E41) -> 41 | F39: =SUM(F40:F41) -> 2.7222222 | H39: =SUM(H40:H41) -> 11026.96 | I39: =SUM(I40:I41) -> 15 | J39: =SUM(J40:J41) -> 0.80555556 | K39: =SUM(K40:K41) -> 9980.32 | L39: =SUM(L40:L41) -> 11 | M39: =SUM(M40:M41) -> 0.72916667 | N39: =SUM(N40:N41) -> 0 | O39: =SUM(O40:O41) -> 0 | ... V39: =SUM(V40:V41) -> 1
A40: psych. s 1 - Jirásková | B40: 170000 | C40: =+H40+K40+N40+Q40+T40 -> 37262.54 | D40: =+C40-B40 -> -132737.46 | E40: =+I40+L40+O40+R40+U40 -> 41 | F40: =+J40+M40+P40+S40+V40 -> 2.7222222 | H40: 11026.96 | I40: 15 | J40: 0.80555556 | K40: 9980.32 | L40: 11 | M40: 0.72916667 | Q40: 2566.62 | R40: 3 | S40: 0.1875 | T40: 13688.64 | U40: 12 | V40: 1
...

Sheet květen 2025
A1: VÝNOSY | H1: týden 1 (zpravidla dělený s předchozím měsícem) | K1: týden 2 | N1: týden 3 | Q1: týden 4 | T1: týden 5 (zpravidla dělený s následujícím měsícem)
A2: Středisko/pracovník | B2: plán měsíce | C2: skutečnost měsíce | D2: rozdíl | E2: počet intervencí | F2: odpracováno hod. | H2: výkony /týden | I2: počet intervencí | J2: odpracováno hod. | K2: výkony /týden | L2: počet intervencí | M2: odpracováno hod. | N2: výkony /týden | O2: počet intervencí | P2: odpracováno hod. | Q2: výkony /týden | R2: počet intervencí | S2: odpracováno hod. | T2: výkony /týden | U2: počet intervencí | V2: odpracováno hod.
A3: výnosy CDZ Ústí | B3: =SUM(B4:B12) -> 1365000 | C3: =SUM(C4:C12) -> 1086204.6 | D3: =SUM(D4:D12) -> -278795.4 | E3: =SUM(E4:E12) -> 855 | F3: =SUM(F4:F12) -> 54.780139 | H3: =SUM(H4:H12) -> 29176.2 | I3: =SUM(I4:I12) -> 22 | J3: =SUM(J4:J12) -> 1.4513889 | K3: =SUM(K4:K12) -> 239587.2 | L3: =SUM(L4:L12) -> 179 | M3: =SUM(M4:M12) -> 11.767361 | N3: =SUM(N4:N12) -> 251622.72 | O3: =SUM(O4:O12) -> 179 | ... V3: =SUM(V4:V12) -> 15.189861
A4: psych. s. 1 - NÁGLOVÁ | B4: 200000 | C4: =+H4+K4+N4+Q4+T4 -> 188739.72 | D4: =+C4-B4 -> -11260.28 | E4: =+I4+L4+O4+R4+U4 -> 212 | F4: =+J4+M4+P4+S4+V4 -> 11.572917 | K4: 41727.96 | L4: 45 | M4: 2.5173611 | N4: 52626.24 | O4: 44 | P4: 3.1944444 | Q4: 49898.16 | R4: 62 | S4: 3.0590278 | T4: 44487.36 | U4: 61 | V4: 2.8020833
A5: psych. s. 2 - HAJASOVÁ | B5: 200000 | C5: =+H5+K5+N5+Q5+T5 -> 102938.04 | D5: =+C5-B5 -> -97061.96 | E5: =+I5+L5+O5+R5+U5 -> 86 | F5: =+J5+M5+P5+S5+V5 -> 6.5069444 | H5: 6285.6 | I5: 5 | J5: 0.41666667 | K5: 12571.2 | L5: 10 | M5: 0.83333333 | Q5: 39590.64 | R5: 33 | S5: 2.5 | T5: 44490.6 | U5: 38 | V5: 2.7569444
A6: psych. s. 3 - KAŠPÁRKOVÁ/Pekárová | B6: 200000 | C6: =+H6+K6+N6+Q6+T6 -> 154528.56 | D6: =+C6-B6 -> -45471.44 | E6: =+I6+L6+O6+R6+U6 -> 135 | F6: =+J6+M6+P6+S6+V6 -> 9.6586111 | K6: 28513.08 | L6: 24 | M6: 1.7430556 | N6: 48420.72 | O6: 41 | P6: 2.9722222 | Q6: 31428 | R6: 25 | S6: 2.0833333 | T6: 46166.76 | U6: 45 | V6: 2.86
A7: psych. s. 4 - | B7: 0 | C7: =+H7+K7+N7+Q7+T7 -> 0 | D7: =+C7-B7 -> 0 | E7: =+I7+L7+O7+R7+U7 -> 0 | F7: =+J7+M7+P7+S7+V7 -> 0
A8: psychiatr - GÁBEL 0,2 | B8: =450000*0.2 -> 90000 | C8: =+H8+K8+N8+Q8+T8 -> 12361.68 | D8: =+C8-B8 -> -77638.32 | E8: =+I8+L8+O8+R8+U8 -> 20 | F8: =+J8+M8+P8+S8+V8 -> 0.625 | N8: 4795.2 | O8: 6 | P8: 0.25 | Q8: 4990.68 | R8: 7 | S8: 0.25694444 | T8: 2575.8 | U8: 7 | V8: 0.11805556
A9: psychiatr - PFEIFFER 0,5 | B9: =450000*0.5 -> 225000 | C9: =+H9+K9+N9+Q9+T9 -> 216265.68 | D9: =+C9-B9 -> -8734.32 | E9: =+I9+L9+O9+R9+U9 -> 158 | F9: =+J9+M9+P9+S9+V9 -> 9.0625 | K9: 68507.64 | L9: 45 | M9: 2.8819444 | N9: 49480.2 | O9: 37 | P9: 2.0138889 | Q9: 52822.8 | R9: 35 | S9: 2.1458333 | T9: 45455.04 | U9: 41 | V9: 2.0208333
A10: psychiatr - Dr. Suchánková 1,0 | B10: =450000 -> 450000 | C10: =+H10+K10+N10+Q10+T10 -> 396842.76 | D10: =+C10-B10 -> -53157.24 | E10: =+I10+L10+O10+R10+U10 -> 238 | F10: =+J10+M10+P10+S10+V10 -> 16.854167 | H10: 22890.6 | I10: 17 | J10: 1.0347222 | K10: 88267.32 | L10: 55 | M10: 3.7916667 | N10: 96300.36 | O10: 51 | P10: 4.0902778 | Q10: 86546.88 | R10: 53 | S10: 3.6388889 | T10: 102837.6 | U10: 62 | V10: 4.2986111
A11: psycholog 1 - Dr. Balko 0,2 | B11: 0 | C11: =+H11+K11+N11+Q11+T11 -> 14528.16 | D11: =+C11-B11 -> 14528.16 | E11: =+I11+L11+O11+R11+U11 -> 6 | F11: =+J11+M11+P11+S11+V11 -> 0.5 | Q11: 4842.72 | R11: 2 | S11: 0.16666667 | T11: 9685.44 | U11: 4 | V11: 0.33333333
A12: psycholog 2 - Lichtenbergová | B12: 0 | C12: =+H12+K12+N12+Q12+T12 -> 0 | D12: =+C12-B12 -> 0 | E12: =+I12+L12+O12+R12+U12 -> 0 | F12: =+J12+M12+P12+S12+V12 -> 0
A13: výnosy CDZ Chomutov | B13: =SUM(B14:B21) -> 340000 | C13: =SUM(C14:C21) -> 210552.02 | D13: =SUM(D14:D21) -> -129447.98 | E13: =SUM(E14:E21) -> 252 | F13: =SUM(F14:F21) -> 15.381944 | H13: =SUM(H14:H21) -> 8934.66 | I13: =SUM(I14:I21) -> 12 | J13: =SUM(J14:J21) -> 0.65277778 | K13: =SUM(K14:K21) -> 35076.16 | L13: =SUM(L14:L21) -> 51 | M13: =SUM(M14:M21) -> 2.5625 | N13: =SUM(N14:N21) -> 57366.26 | O13: =SUM(O14:O21) -> 68 | ... V13: =SUM(V14:V21) -> 3.9513889
A14: psych. s 1 - Blažková | B14: =200000*0.85 -> 170000 | C14: =+H14+K14+N14+Q14+T14 -> 112071.82 | D14: =+C14-B14 -> -57928.18 | E14: =+I14+L14+O14+R14+U14 -> 153 | F14: =+J14+M14+P14+S14+V14 -> 8.1875 | H14: 4848.06 | I14: 6 | J14: 0.35416667 | K14: 21292.46 | L14: 35 | M14: 1.5555556 | N14: 29894.9 | O14: 43 | P14: 2.1840278 | Q14: 26093.48 | R14: 31 | S14: 1.90625 | T14: 29942.92 | U14: 38 | V14: 2.1875
A15: psych. s 2 - Pátková od 1.3 | B15: =200000*0.85 -> 170000 | C15: =+H15+K15+N15+Q15+T15 -> 98480.2 | D15: =+C15-B15 -> -71519.8 | E15: =+I15+L15+O15+R15+U15 -> 99 | F15: =+J15+M15+P15+S15+V15 -> 7.1944444 | H15: 4086.6 | I15: 6 | J15: 0.29861111 | K15: 13783.7 | L15: 16 | M15: 1.0069444 | N15: 27471.36 | O15: 25 | P15: 2.0069444 | Q15: 28993.3 | R15: 29 | S15: 2.1180556 | T15: 24145.24 | U15: 23 | V15: 1.7638889
A16: psych. s 3 | B16: 0 | C16: =+H16+K16+N16+Q16+T16 -> 0 | D16: =+C16-B16 -> 0 | E16: =+I16+L16+O16+R16+U16 -> 0 | F16: =+J16+M16+P16+S16+V16 -> 0
A17: psych. s 4 | B17: 0 | C17: =+H17+K17+N17+Q17+T17 -> 0 | D17: =+C17-B17 -> 0 | E17: =+I17+L17+O17+R17+U17 -> 0 | F17: =+J17+M17+P17+S17+V17 -> 0
A18: psychiatr 1 - 0,5 od 1.4 | B18: 0 | C18: =+H18+K18+N18+Q18+T18 -> 0 | D18: =+C18-B18 -> 0 | E18: =+I18+L18+O18+R18+U18 -> 0 | F18: =+J18+M18+P18+S18+V18 -> 0
A19: psychiatr 2 | B19: 0 | C19: =+H19+K19+N19+Q19+T19 -> 0 | D19: =+C19-B19 -> 0 | E19: =+I19+L19+O19+R19+U19 -> 0 | F19: =+J19+M19+P19+S19+V19 -> 0
A20: psycholog 1 - 0,5 | B20: 0 | C20: =+H20+K20+N20+Q20+T20 -> 0 | D20: =+C20-B20 -> 0 | E20: =+I20+L20+O20+R20+U20 -> 0 | F20: =+J20+M20+P20+S20+V20 -> 0
A21: psycholog 2 | B21: 0 | C21: =+H21+K21+N21+Q21+T21 -> 0 | D21: =+C21-B21 -> 0 | E21: =+I21+L21+O21+R21+U21 -> 0 | F21: =+J21+M21+P21+S21+V21 -> 0
A22: výnosy CDZ Žatec | B22: =SUM(B23:B30) -> 510000 | C22: =SUM(C23:C30) -> 299045.04 | D22: =SUM(D23:D30) -> -210954.96 | E22: =SUM(E23:E30) -> 311 | F22: =SUM(F23:F30) -> 21.847222 | H22: =SUM(H23:H30) -> 10550.68 | I22: =SUM(I23:I30) -> 12 | J22: =SUM(J23:J30) -> 0.77083333 | K22: =SUM(K23:K30) -> 59409.56 | L22: =SUM(L23:L30) -> 54 | M22: =SUM(M23:M30) -> 4.3402778 | N22: =SUM(N23:N30) -> 74144.84 | O22: =SUM(O23:O30) -> 77 | ... V22: =SUM(V23:V30) -> 5.6458333
A23: psych. s 1 - ZELENKOVÁ | B23: =200000*0.85 -> 170000 | C23: =+H23+K23+N23+Q23+T23 -> 114920.68 | D23: =+C23-B23 -> -55079.32 | E23: =+I23+L23+O23+R23+U23 -> 125 | F23: =+J23+M23+P23+S23+V23 -> 8.3958333 | H23: 5987.8 | I23: 8 | J23: 0.4375 | K23: 23858.1 | L23: 27 | M23: 1.7430556 | N23: 27282.22 | O23: 27 | P23: 1.9930556 | Q23: 30035.04 | R23: 32 | S23: 2.1944444 | T23: 27757.52 | U23: 31 | V23: 2.0277778
A24: psych. s 2 - Vondráčková | B24: =200000*0.85 -> 170000 | C24: =+H24+K24+N24+Q24+T24 -> 91253.68 | D24: =+C24-B24 -> -78746.32 | E24: =+I24+L24+O24+R24+U24 -> 97 | F24: =+J24+M24+P24+S24+V24 -> 6.6666667 | H24: 2281.44 | I24: 2 | J24: 0.16666667 | K24: 17681.16 | L24: 13 | M24: 1.2916667 | N24: 22907.5 | O24: 28 | P24: 1.6736111 | Q24: 24240.3 | R24: 25 | S24: 1.7708333 | T24: 24143.28 | U24: 29 | V24: 1.7638889
A25: psych. s 3 - Nováková | B25: =200000*0.85 -> 170000 | C25: =+H25+K25+N25+Q25+T25 -> 92870.68 | D25: =+C25-B25 -> -77129.32 | E25: =+I25+L25+O25+R25+U25 -> 89 | F25: =+J25+M25+P25+S25+V25 -> 6.7847222 | H25: 2281.44 | I25: 2 | J25: 0.16666667 | K25: 17870.3 | L25: 14 | M25: 1.3055556 | N25: 23955.12 | O25: 22 | P25: 1.75 | Q25: 23383.78 | R25: 25 | S25: 1.7083333 | T25: 25380.04 | U25: 26 | V25: 1.8541667
A26: všeob. s 4 - Dušková | B26: 0 | C26: =+H26+K26+N26+Q26+T26 -> 0 | D26: =+C26-B26 -> 0 | E26: =+I26+L26+O26+R26+U26 -> 0 | F26: =+J26+M26+P26+S26+V26 -> 0
A27: psychiatr 1 - 0,5 od 1.4 | B27: 0 | C27: =+H27+K27+N27+Q27+T27 -> 0 | D27: =+C27-B27 -> 0 | E27: =+I27+L27+O27+R27+U27 -> 0 | F27: =+J27+M27+P27+S27+V27 -> 0
A28: psychiatr 2 | B28: 0 | C28: =+H28+K28+N28+Q28+T28 -> 0 | D28: =+C28-B28 -> 0 | E28: =+I28+L28+O28+R28+U28 -> 0 | F28: =+J28+M28+P28+S28+V28 -> 0
A29: psycholog 1 - 0,5 | B29: 0 | C29: =+H29+K29+N29+Q29+T29 -> 0 | D29: =+C29-B29 -> 0 | E29: =+I29+L29+O29+R29+U29 -> 0 | F29: =+J29+M29+P29+S29+V29 -> 0
A30: psycholog 2 | B30: 0 | C30: =+H30+K30+N30+Q30+T30 -> 0 | D30: =+C30-B30 -> 0 | E30: =+I30+L30+O30+R30+U30 -> 0 | F30: =+J30+M30+P30+S30+V30 -> 0
A31: výnosy CDZ Litoměřice | B31: =SUM(B32:B39) -> 170000 | C31: =SUM(C32:C39) -> 105996.8 | D31: =SUM(D32:D39) -> -64003.2 | E31: =SUM(E32:E39) -> 114 | F31: =SUM(F32:F39) -> 7.7395833 | H31: =SUM(H32:H39) -> 6273.96 | I31: =SUM(I32:I39) -> 7 | J31: =SUM(J32:J39) -> 0.45833333 | K31: =SUM(K32:K39) -> 21055.3 | L31: =SUM(L32:L39) -> 24 | M31: =SUM(M32:M39) -> 1.5381944 | N31: =SUM(N32:N39) -> 22434.16 | O31: =SUM(O32:O39) -> 25 | ... V31: =SUM(V32:V39) -> 2.0173611
A32: psych. s 1 - Štréblová 0,2 od 1.3 od 5 celý | B32: =200000*0.85 -> 170000 | C32: =+H32+K32+N32+Q32+T32 -> 105996.8 | D32: =+C32-B32 -> -64003.2 | E32: =+I32+L32+O32+R32+U32 -> 114 | F32: =+J32+M32+P32+S32+V32 -> 7.7395833 | H32: 6273.96 | I32: 7 | J32: 0.45833333 | K32: 21055.3 | L32: 24 | M32: 1.5381944 | N32: 22434.16 | O32: 25 | P32: 1.6388889 | Q32: 28618.94 | R32: 28 | S32: 2.0868056 | T32: 27614.44 | U32: 30 | V32: 2.0173611
A33: psych. s 2 | B33: 0 | C33: =+H33+K33+N33+Q33+T33 -> 0 | D33: =+C33-B33 -> 0 | E33: =+I33+L33+O33+R33+U33 -> 0 | F33: =+J33+M33+P33+S33+V33 -> 0
A34: psych. s 3 | B34: 0 | C34: =+H34+K34+N34+Q34+T34 -> 0 | D34: =+C34-B34 -> 0 | E34: =+I34+L34+O34+R34+U34 -> 0 | F34: =+J34+M34+P34+S34+V34 -> 0
A35: psych. s 4 | B35: 0 | C35: =+H35+K35+N35+Q35+T35 -> 0 | D35: =+C35-B35 -> 0 | E35: =+I35+L35+O35+R35+U35 -> 0 | F35: =+J35+M35+P35+S35+V35 -> 0
A36: psychiatr 1 - 0,5 | B36: 0 | C36: =+H36+K36+N36+Q36+T36 -> 0 | D36: =+C36-B36 -> 0 | E36: =+I36+L36+O36+R36+U36 -> 0 | F36: =+J36+M36+P36+S36+V36 -> 0
A37: psychiatr 2 | B37: 0 | C37: =+H37+K37+N37+Q37+T37 -> 0 | D37: =+C37-B37 -> 0 | E37: =+I37+L37+O37+R37+U37 -> 0 | F37: =+J37+M37+P37+S37+V37 -> 0
A38: psycholog 1 - 0,5 | B38: 0 | C38: =+H38+K38+N38+Q38+T38 -> 0 | D38: =+C38-B38 -> 0 | E38: =+I38+L38+O38+R38+U38 -> 0 | F38: =+J38+M38+P38+S38+V38 -> 0
A39: psycholog 2 | B39: 0 | C39: =+H39+K39+N39+Q39+T39 -> 0 | D39: =+C39-B39 -> 0 | E39: =+I39+L39+O39+R39+U39 -> 0 | F39: =+J39+M39+P39+S39+V39 -> 0
A40: výnosy TDZ Děčín | B40: =SUM(B41:B42) -> 0 | C40: =SUM(C41:C42) -> 0 | D40: =SUM(D41:D42) -> 0 | E40: =SUM(E41:E42) -> 0 | F40: =SUM(F41:F42) -> 0 | H40: =SUM(H41:H42) -> 0 | I40: =SUM(I41:I42) -> 0 | J40: =SUM(J41:J42) -> 0 | K40: =SUM(K41:K42) -> 0 | L40: =SUM(L41:L42) -> 0 | M40: =SUM(M41:M42) -> 0 | N40: =SUM(N41:N42) -> 0 | O40: =SUM(O41:O42) -> 0 | ... V40: =SUM(V41:V42) -> 0
...

Sheet červen 2025
A1: VÝNOSY | H1: týden 1 (zpravidla dělený s předchozím měsícem) | K1: týden 2 | N1: týden 3 | Q1: týden 4 | T1: týden 5 (zpravidla dělený s následujícím měsícem)
A2: Středisko/pracovník | B2: plán měsíce | C2: skutečnost měsíce | D2: rozdíl | E2: počet intervencí | F2: odpracováno hod. | H2: výkony /týden | I2: počet intervencí | J2: odpracováno hod. | K2: výkony /týden | L2: počet intervencí | M2: odpracováno hod. | N2: výkony /týden | O2: počet intervencí | P2: odpracováno hod. | Q2: výkony /týden | R2: počet intervencí | S2: odpracováno hod. | T2: výkony /týden | U2: počet intervencí | V2: odpracováno hod.
A3: výnosy CDZ Ústí | B3: =SUM(B4:B12) -> 1165000 | C3: =SUM(C4:C12) -> 1201249.8 | D3: =SUM(D4:D12) -> 36249.76 | E3: =SUM(E4:E12) -> 955 | F3: =SUM(F4:F12) -> 60.368056 | H3: =SUM(H4:H12) -> 329425.92 | I3: =SUM(I4:I12) -> 262 | J3: =SUM(J4:J12) -> 16.28125 | K3: =SUM(K4:K12) -> 298428.08 | L3: =SUM(L4:L12) -> 231 | M3: =SUM(M4:M12) -> 14.645833 | N3: =SUM(N4:N12) -> 277615.08 | O3: =SUM(O4:O12) -> 214 | ... V3: =SUM(V4:V12) -> 2.7152778
A4: psych. s. 1 - NÁGLOVÁ | B4: 200000 | C4: =+H4+K4+N4+Q4+T4 -> 205111.76 | D4: =+C4-B4 -> 5111.76 | E4: =+I4+L4+O4+R4+U4 -> 223 | F4: =+J4+M4+P4+S4+V4 -> 12.576389 | H4: 41449.32 | I4: 45 | J4: 2.6006944 | K4: 55616 | L4: 64 | M4: 3.3333333 | N4: 45092.16 | O4: 47 | P4: 2.7743056 | Q4: 50340.96 | R4: 55 | S4: 3.1111111 | T4: 12613.32 | U4: 12 | V4: 0.75694444
A5: psych. s. 2 - HAJASOVÁ | B5: 200000 | C5: =+H5+K5+N5+Q5+T5 -> 128852.64 | D5: =+C5-B5 -> -71147.36 | E5: =+I5+L5+O5+R5+U5 -> 113 | F5: =+J5+M5+P5+S5+V5 -> 8.2361111 | H5: 32020.92 | I5: 27 | J5: 2.0208333 | K5: 23442.48 | L5: 22 | M5: 1.4861111 | N5: 30880.44 | O5: 27 | P5: 1.9791667 | Q5: 34624.8 | R5: 31 | S5: 2.25 | T5: 7884 | U5: 6 | V5: 0.5
A6: psych. s. 3 - KAŠPÁRKOVÁ/Pekárová | B6: 200000 | C6: =+H6+K6+N6+Q6+T6 -> 151512.12 | D6: =+C6-B6 -> -48487.88 | E6: =+I6+L6+O6+R6+U6 -> 141 | F6: =+J6+M6+P6+S6+V6 -> 9.3680556 | H6: 53070.12 | I6: 52 | J6: 3.2013889 | K6: 22628.16 | L6: 18 | M6: 1.5 | N6: 31428 | O6: 25 | P6: 2.0833333 | Q6: 35702.64 | R6: 40 | S6: 2.0416667 | T6: 8683.2 | U6: 6 | V6: 0.54166667
A7: psychiatr - Dr. Holá 0,2 | B7: 0 | C7: =+H7+K7+N7+Q7+T7 -> 80771.04 | D7: =+C7-B7 -> 80771.04 | E7: =+I7+L7+O7+R7+U7 -> 49 | F7: =+J7+M7+P7+S7+V7 -> 3.3819444 | H7: 20129.04 | I7: 10 | J7: 0.80555556 | K7: 19632.24 | L7: 13 | M7: 0.81944444 | N7: 17665.56 | O7: 11 | P7: 0.75 | Q7: 23344.2 | R7: 15 | S7: 1.0069444
A8: psychiatr - GÁBEL 0,2 | B8: =450000*0.2 -> 90000 | C8: =+H8+K8+N8+Q8+T8 -> 11723.4 | D8: =+C8-B8 -> -78276.6 | E8: =+I8+L8+O8+R8+U8 -> 25 | F8: =+J8+M8+P8+S8+V8 -> 0.58333333 | H8: 4990.68 | I8: 7 | J8: 0.27777778 | K8: 1776.6 | L8: 6 | M8: 0.076388889 | N8: 2984.04 | O8: 6 | P8: 0.14583333 | Q8: 1972.08 | R8: 6 | S8: 0.083333333
A9: psychiatr - PFEIFFER 0,5 | B9: =450000*0.5 -> 225000 | C9: =+H9+K9+N9+Q9+T9 -> 167688.36 | D9: =+C9-B9 -> -57311.64 | E9: =+I9+L9+O9+R9+U9 -> 122 | F9: =+J9+M9+P9+S9+V9 -> 7.0902778 | H9: 63406.8 | I9: 45 | J9: 2.5902778 | K9: 53291.52 | L9: 39 | M9: 2.3055556 | N9: 50990.04 | O9: 38 | P9: 2.1944444
